<sdf version='1.4'>
  <model name='robot'>
    
  <link name='base_footprint'>
      <pose>0 0 0 0 -0 0</pose>
      <inertial>
        <pose>-0.000133842 0 0.000672573 0 -0 0</pose>
        <mass>3.5101</mass>
        <inertia>
          <ixx>4.00055</ixx>
          <ixy>0</ixy>
          <ixz>0.000109102</ixz>
          <iyy>4.00057</iyy>
          <iyz>0</iyz>
          <izz>4.00002</izz>
        </inertia>
      </inertial>

      <collision name='base_link_collision'>
        <pose>0 0 0.0985 0 -0 0</pose>
        <geometry>
          <box>
            <size>0.455 0.381 0.01</size>
          </box>
        </geometry>
      </collision>

	  <!-- The visual elements and the used models are from https://github.com/MobileRobots/amr-ros-config (https://github.com/MobileRobots/amr-ros-config/tree/master/description/meshes/p3dx_meshes) -->
      <visual name='base_footprint_visual'>
        <pose>-0.045 0 0.148 0 -0 0</pose>
        <geometry>
          <mesh>
            <scale>1 1 1</scale>
            <uri>models/pioneer/description/meshes/p3dx_meshes/chassis.stl</uri>
          </mesh>
        </geometry>
		<!-- Adapted color -->
  		<material>
    		<ambient>0.851 0.5 0 1</ambient>
    		<diffuse>0.851 0 0 1</diffuse>
    		<specular>0 0 0 1</specular>
    		<emissive>0 0 0 1</emissive>
  		</material>
      </visual>

      <visual name='wheel_right_hubcap_visual'>
        <pose>0 -0.15 0.08 0 -0 0</pose>
        <geometry>
          <mesh>
            <scale>1 1 1</scale>
            <uri>models/pioneer/description/meshes/p3dx_meshes/right_hubcap.stl</uri>
          </mesh>
        </geometry>
		<!-- Adapted color -->
  		<material>
    		<ambient>0.851 0.5 0 1</ambient>
    		<diffuse>0.851 0 0 1</diffuse>
    		<specular>0 0 0 1</specular>
    		<emissive>0 0 0 1</emissive>
  		</material>
      </visual>

      <visual name='wheel_left_hubcap_visual'>
        <pose>0 0.15 0.08 0 -0 0</pose>
        <geometry>
          <mesh>
            <scale>1 1 1</scale>
            <uri>models/pioneer/description/meshes/p3dx_meshes/left_hubcap.stl</uri>
          </mesh>
        </geometry>
		<!-- Timo -->
  		<material>
    		<ambient>0.851 0.5 0 1</ambient>
    		<diffuse>0.851 0 0 1</diffuse>
    		<specular>0 0 0 1</specular>
    		<emissive>0 0 0 1</emissive>
  		</material>
      </visual>

      <visual name='caster_swivel_visual'>
        <pose>-0.185 0 0.055 0 -0 0</pose>
        <geometry>
          <mesh>
            <scale>1 1 1</scale>
            <uri>models/pioneer/description/meshes/p3dx_meshes/caster_swivel.stl</uri>
          </mesh>
        </geometry>
        <material>
          <script>
            <name>Gazebo/DarkGrey</name>
            <uri>__default__</uri>
          </script>
        </material>
      </visual>

      <visual name='caster_wheel_visual'>
        <pose>-0.211 0 0.039 0 -0 0</pose>
        <geometry>
          <mesh>
            <scale>1 1 1</scale>
            <uri>models/pioneer/description/meshes/p3dx_meshes/caster_wheel.stl</uri>
          </mesh>
        </geometry>
        <material>
          <script>
            <name>Gazebo/DarkGrey</name>
            <uri>__default__</uri>
          </script>
        </material>
      </visual>

      <visual name='base_link_visual_base_link_1'>
        <pose>0.109 0 0.209 0 -0 0</pose>
        <geometry>
          <mesh>
            <scale>1 1 1</scale>
            <uri>models/pioneer/description/meshes/p3dx_meshes/back_sonar.stl</uri>
          </mesh>
        </geometry>
		<!-- Adapted color -->
  		<material>
    		<ambient>0.715 0.583 0.210 1</ambient>
    		<diffuse>0.715 0.583 0.210 1</diffuse>
    		<specular>0.715 0.583 0.210 1</specular>
    		<emissive>0.715 0.583 0.210 1</emissive>
  		</material>
      </visual>

      <visual name='base_link_visual_base_link_2'>
        <pose>-0.198 0 0.208 0 -0 0</pose>
        <geometry>
          <mesh>
            <scale>1 1 1</scale>
            <uri>models/pioneer/description/meshes/p3dx_meshes/front_sonar.stl</uri>
          </mesh>
        </geometry>
		<!-- Adapted color -->
  		<material>
    		<ambient>0.715 0.583 0.210 1</ambient>
    		<diffuse>0.715 0.583 0.210 1</diffuse>
    		<specular>0.715 0.583 0.210 1</specular>
    		<emissive>0.715 0.583 0.210 1</emissive>
  		</material>
      </visual>

      <visual name='base_link_visual_base_link_3'>
        <pose>-0.045 0 0.234 0 -0 0</pose>
        <geometry>
          <mesh>
            <scale>1 1 1</scale>
            <uri>models/pioneer/description/meshes/p3dx_meshes/top.stl</uri>
          </mesh>
        </geometry>
		<!-- Adapted color -->
  		<material>
    		<ambient>0.038 0.038 0.038 1</ambient>
    		<diffuse>0.038 0.038 0.038 1</diffuse>
    		<specular>0 0 0 1</specular>
    		<emissive>0 0 0 1</emissive>
  		</material>
      </visual>

      <!-- End of visual elements -->

	<!-- Timo: Added imu sensor [start] -->
      <sensor name='base_imu_sensor' type='imu'>
        <always_on>1</always_on>
        <update_rate>100</update_rate>
        <imu>
          <noise>
            <type>gaussian</type>
            <rate>
              <mean>0</mean>
              <stddev>0.0002</stddev>
              <bias_mean>7.5e-06</bias_mean>
              <bias_stddev>8e-07</bias_stddev>
            </rate>
            <accel>
              <mean>0</mean>
              <stddev>0.017</stddev>
              <bias_mean>0.1</bias_mean>
              <bias_stddev>0.001</bias_stddev>
            </accel>
          </noise>
        </imu>
        <pose>0.10171 0 0.21132 0 0 -1.5708</pose>
      </sensor>
	<!-- Timo: Added imu sensor [end] -->

      <sensor name='base_laser' type='ray'>
        <update_rate>10</update_rate>
        <visualize>1</visualize>
        <ray>
          <scan>
            <horizontal>
              <samples>640</samples>
              <resolution>1</resolution>
              <min_angle>-1.91986</min_angle>
              <max_angle>1.91986</max_angle>
            </horizontal>
          </scan>
          <range>
            <min>0.05</min>
            <max>10</max>
            <resolution>0.001</resolution>
          </range>
        </ray>
        <pose>0.150 0 0.305 0 -0 0</pose>
	  </sensor>

	  <!-- This laser model is from https://github.com/pal-robotics/pmb2_robot/tree/indigo-devel/pmb2_description -->
	  <visual name='base_footprint_visual_base_laser_link'>
        <pose>0.150 0 0.305 0 -0 0</pose>
        <geometry>
          <mesh>
            <scale>1 1 1</scale>
            <uri>models/tiago/pmb2_description/meshes/sensors/sick_tim551.stl</uri>
          </mesh>
        </geometry>
        <material>
          <script>
            <name>Gazebo/White</name>
            <uri>__default__</uri>
          </script>
        </material>
      </visual>

	  <!-- End of laser element -->

	</link>
 
	<!-- The link and joint elements of the left and right wheel are from https://github.com/pal-robotics/pmb2_robot/tree/indigo-devel/pmb2_description.
         The models for visualization are from https://github.com/MobileRobots/amr-ros-config (https://github.com/MobileRobots/amr-ros-config/tree/master/description/meshes/p3dx_meshes)
    -->
    <link name='wheel_left_link'>
      <!--<pose>0 0.2022 0.0985 -1.5708 0 0</pose>-->
	  <pose>0 0.15 0.08 -1.5708 -0 0</pose>
      <inertial>
        <pose>0 0 0.00207 0 -0 0</pose>
        <mass>1.82362</mass>
        <inertia>
          <ixx>0.00499743</ixx>
          <ixy>-4.464e-08</ixy>
          <ixz>-2.245e-08</ixz>
          <iyy>0.00499742</iyy>
          <iyz>1.64e-09</iyz>
          <izz>0.0083924</izz>
        </inertia>
      </inertial>
      <collision name='wheel_left_link_collision'>
        <pose>0 0 0 0 -0 0</pose>
        <geometry>
          <cylinder>
            <length>0.04</length>
            <radius>0.0985</radius>
          </cylinder>
        </geometry>
        <surface>
          <contact>
            <ode>
              <kp>1e+06</kp>
              <kd>100</kd>
              <max_vel>1</max_vel>
              <min_depth>0.003</min_depth>
            </ode>
          </contact>
          <friction>
            <ode>
              <mu>1</mu>
              <mu2>1</mu2>
              <fdir1>1 0 0</fdir1>
            </ode>
          </friction>
        </surface>
      </collision>
      <visual name='wheel_left_link_visual'>
        <pose>0 0 0 0 -0 0</pose>
        <geometry>
          <mesh>
            <scale>1 1 1</scale>
            <uri>models/pioneer/description/meshes/p3dx_meshes/left_wheel.stl</uri>
          </mesh>
        </geometry>
        <material>
          <script>
            <name>Gazebo/DarkGrey</name>
            <uri>__default__</uri>
          </script>
        </material>
      </visual>
      <gravity>1</gravity>
      <velocity_decay>
        <linear>0</linear>
        <angular>0</angular>
      </velocity_decay>
      <self_collide>0</self_collide>
    </link>
    <joint name='wheel_left_joint' type='revolute'>
      <child>wheel_left_link</child>
      <parent>base_footprint</parent>
      <axis>
        <xyz>0 1 4.89658e-12</xyz>
        <limit>
          <lower>-1e+16</lower>
          <upper>1e+16</upper>
        </limit>
        <dynamics/>
      </axis>
    </joint>
    <link name='wheel_right_link'>
      <!--<pose>0 -0.2022 0.0985 -1.5708 0 0</pose>-->
	  <pose>0 -0.15 0.08 -1.5708 -0 0</pose>
      <inertial>
        <pose>0 0 -0.00207 0 -0 0</pose>
        <mass>1.82362</mass>
        <inertia>
          <ixx>0.00499743</ixx>
          <ixy>4.464e-08</ixy>
          <ixz>-2.245e-08</ixz>
          <iyy>0.00499742</iyy>
          <iyz>-1.64e-09</iyz>
          <izz>0.0083924</izz>
        </inertia>
      </inertial>
      <collision name='wheel_right_link_collision'>
        <pose>0 0 0 0 -0 0</pose>
        <geometry>
          <cylinder>
            <length>0.04</length>
            <radius>0.0985</radius>
          </cylinder>
        </geometry>
        <surface>
          <contact>
            <ode>
              <kp>1e+06</kp>
              <kd>100</kd>
              <max_vel>1</max_vel>
              <min_depth>0.003</min_depth>
            </ode>
          </contact>
          <friction>
            <ode>
              <mu>1</mu>
              <mu2>1</mu2>
              <fdir1>1 0 0</fdir1>
            </ode>
          </friction>
        </surface>
      </collision>
      <visual name='wheel_right_link_visual'>
		<pose>0 0 0 0 0 0</pose>
        <geometry>
          <mesh>
            <scale>1 1 1</scale>
            <uri>models/pioneer/description/meshes/p3dx_meshes/right_wheel.stl</uri>
          </mesh>
        </geometry>
        <material>
          <script>
            <name>Gazebo/DarkGrey</name>
            <uri>__default__</uri>
          </script>
        </material>
      </visual>
      <gravity>1</gravity>
      <velocity_decay>
        <linear>0</linear>
        <angular>0</angular>
      </velocity_decay>
      <self_collide>0</self_collide>
    </link>
    <joint name='wheel_right_joint' type='revolute'>
      <child>wheel_right_link</child>
      <parent>base_footprint</parent>
      <axis>
        <xyz>0 1 4.89658e-12</xyz>
        <limit>
          <lower>-1e+16</lower>
          <upper>1e+16</upper>
        </limit>
        <dynamics/>
      </axis>
    </joint>

    <!-- End of joint and link elements -->

  </model>
</sdf>
