<sdf version='1.4'>
  <model name='robot'>

    <link name='torso_lift_link'>
      <pose>-0.062 0 0.8785 0 -0 0</pose>
      <inertial>
        <pose>0.04361 -0.00116 -0.17334 0 -0 0</pose>
        <mass>6.93198</mass>
        <inertia>
          <ixx>0.24487</ixx>
          <ixy>-0.001456</ixy>
          <ixz>-0.009742</ixz>
          <iyy>0.249269</iyy>
          <iyz>0.008281</iyz>
          <izz>0.090395</izz>
        </inertia>
      </inertial>
      <velocity_decay/>
      <gravity>0</gravity>
      <velocity_decay/>
    </link>

    <link name='arm_1_link'>
	  <static>0</static>
      <pose frame=''>0.071050 0.014000 0.65100 0 0 -1.5708</pose>
      <inertial>
        <pose frame=''>0.08169 0.01822 -0.01884 0 -0 0</pose>
        <mass>2.31325</mass>
        <inertia>
          <ixx>0.002694</ixx>
          <ixy>0.001157</ixy>
          <ixz>-0.001423</ixz>
          <iyy>0.007041</iyy>
          <iyz>-0.000312</iyz>
          <izz>0.007312</izz>
        </inertia>
      </inertial>
      <!--<collision name='arm_1_link_collision'>
        <pose frame=''>0 0 0 0 -0 0</pose>
        <geometry>
          <mesh>
            <scale>1 1 1</scale>
            <uri>models/tiago/tiago_description/meshes/arm/arm_1_collision.dae</uri>
          </mesh>
        </geometry>
        <surface>
          <contact>
            <ode/>
          </contact>
          <friction>
            <ode>
              <mu>0.9</mu>
              <mu2>0.9</mu2>
            </ode>
          </friction>
        </surface>
      </collision>-->
      <visual name='arm_1_link_visual'>
        <pose frame=''>0 0 0 0 -0 0</pose>
        <geometry>
          <mesh>
            <scale>1 1 1</scale>
            <uri>models/tiago/tiago_description/meshes/arm/arm_1.stl</uri>
          </mesh>
        </geometry>
        <material>
          <script>
            <name>Gazebo/DarkGrey</name>
            <uri>file://media/materials/scripts/gazebo.material</uri>
          </script>
        </material>
      </visual>
      <velocity_decay/>
      <gravity>0</gravity>
      <velocity_decay/>
    </link>

    <joint name='arm_1_joint' type='revolute'>
      <child>arm_1_link</child>
      <parent>torso_lift_link</parent>
      <axis>
        <xyz>0 0 1</xyz>
        <limit>
          <lower>0</lower>
          <upper>2.74889</upper>
          <effort>39</effort>
          <velocity>2.7</velocity>
        </limit>
        <dynamics>
          <damping>1</damping>
          <friction>1</friction>
          <spring_reference>0</spring_reference>
          <spring_stiffness>0</spring_stiffness>
        </dynamics>
        <use_parent_model_frame>1</use_parent_model_frame>
      </axis>
      <physics>
        <ode>
          <implicit_spring_damper>1</implicit_spring_damper>
          <cfm_damping>1</cfm_damping>
          <limit>
            <cfm>0</cfm>
            <erp>0.2</erp>
          </limit>
        </ode>
      </physics>
    </joint>

    <link name='arm_2_link'>
      <pose frame=''>0.087550 -0.111 0.62000 1.5708 0 -1.5708</pose>
      <inertial>
        <pose frame=''>-0.03609 -6e-05 0.01649 0 -0 0</pose>
        <mass>1.10224</mass>
        <inertia>
          <ixx>0.001146</ixx>
          <ixy>1e-06</ixy>
          <ixz>0.000435</ixz>
          <iyy>0.002182</iyy>
          <iyz>-1e-06</iyz>
          <izz>0.002373</izz>
        </inertia>
      </inertial>
      <!--<collision name='arm_2_link_collision'>
        <pose frame=''>0 0 0 0 -0 0</pose>
        <geometry>
          <mesh>
            <scale>1 1 1</scale>
            <uri>models/tiago/tiago_description/meshes/arm/arm_2_collision.dae</uri>
          </mesh>
        </geometry>
        <surface>
          <contact>
            <ode/>
          </contact>
          <friction>
            <ode>
              <mu>0.9</mu>
              <mu2>0.9</mu2>
            </ode>
          </friction>
        </surface>
      </collision>-->
      <visual name='arm_2_link_visual'>
        <pose frame=''>0 0 0 0 -0 0</pose>
        <geometry>
          <mesh>
            <scale>1 1 1</scale>
            <uri>models/tiago/tiago_description/meshes/arm/arm_2.stl</uri>
          </mesh>
        </geometry>
        <material>
          <script>
            <name>Gazebo/DarkGrey</name>
            <uri>file://media/materials/scripts/gazebo.material</uri>
          </script>
        </material>
      </visual>
      <gravity>0</gravity>
      <velocity_decay/>
    </link>

   <joint name='arm_2_joint' type='revolute'>
      <child>arm_2_link</child>
      <parent>arm_1_link</parent>
      <axis>
        <xyz>-1 -0 0</xyz>
        <limit>
          <lower>-1.5708</lower>
          <upper>1.09083</upper>
          <effort>39</effort>
          <velocity>3.66</velocity>
        </limit>
        <dynamics>
          <damping>1</damping>
          <friction>1</friction>
          <spring_reference>0</spring_reference>
          <spring_stiffness>0</spring_stiffness>
        </dynamics>
        <use_parent_model_frame>1</use_parent_model_frame>
      </axis>
      <physics>
        <ode>
          <implicit_spring_damper>1</implicit_spring_damper>
          <cfm_damping>1</cfm_damping>
          <limit>
            <cfm>0</cfm>
            <erp>0.2</erp>
          </limit>
        </ode>
      </physics>
    </joint>

    <link name='arm_3_link'>
      <pose frame=''>0.086050 -0.20050 0.62000 1.57079 -1.57079 3.14159</pose>
      <inertial>
        <pose frame=''>0.00752 0.00244 0.12957 0 -0 0</pose>
        <mass>2.4246</mass>
        <inertia>
          <ixx>0.014418</ixx>
          <ixy>8.4e-05</ixy>
          <ixz>0.001143</ixz>
          <iyy>0.014788</iyy>
          <iyz>0.000642</iyz>
          <izz>0.00256</izz>
        </inertia>
      </inertial>
      <!--<collision name='arm_3_link_collision'>
        <pose frame=''>0 0 0 0 -0 0</pose>
        <geometry>
          <mesh>
            <scale>1 1 1</scale>
            <uri>models/tiago/tiago_description/meshes/arm/arm_3_collision.dae</uri>
          </mesh>
        </geometry>
        <surface>
          <contact>
            <ode/>
          </contact>
          <friction>
            <ode>
              <mu>0.9</mu>
              <mu2>0.9</mu2>
            </ode>
          </friction>
        </surface>
      </collision>-->
      <visual name='arm_3_link_visual'>
        <pose frame=''>0 0 0 0 -0 0</pose>
        <geometry>
          <mesh>
            <scale>1 1 1</scale>
            <uri>models/tiago/tiago_description/meshes/arm/arm_3.stl</uri>
          </mesh>
        </geometry>
        <material>
          <script>
            <name>Gazebo/DarkGrey</name>
            <uri>file://media/materials/scripts/gazebo.material</uri>
          </script>
        </material>
      </visual>
      <gravity>0</gravity>
      <velocity_decay/>
    </link>

    <joint name='arm_3_joint' type='revolute'>
      <child>arm_3_link</child>
      <parent>arm_2_link</parent>
      <axis>
        <xyz>-0 1 0</xyz>
        <limit>
          <lower>-3.53429</lower>
          <upper>1.5708</upper>
          <effort>17.86</effort>
          <velocity>4.58</velocity>
        </limit>
        <dynamics>
          <damping>1</damping>
          <friction>1</friction>
          <spring_reference>0</spring_reference>
          <spring_stiffness>0</spring_stiffness>
        </dynamics>
        <use_parent_model_frame>1</use_parent_model_frame>
      </axis>
      <physics>
        <ode>
          <implicit_spring_damper>1</implicit_spring_damper>
          <cfm_damping>1</cfm_damping>
          <limit>
            <cfm>0</cfm>
            <erp>0.2</erp>
          </limit>
        </ode>
      </physics>
    </joint>

   <link name='arm_4_link'>
      <pose frame=''>0.059050 -0.42250 0.60000 1.5708 -0 1.5708</pose>
      <inertial>
        <pose frame=''>0.07426 -0.01306 0.01549 0 -0 0</pose>
        <mass>1.45429</mass>
        <inertia>
          <ixx>0.001953</ixx>
          <ixy>-0.000596</ixy>
          <ixz>0.00088</ixz>
          <iyy>0.007097</iyy>
          <iyz>-0.000171</iyz>
          <izz>0.007405</izz>
        </inertia>
      </inertial>
      <!--<collision name='arm_4_link_collision'>
        <pose frame=''>0 0 0 0 -0 0</pose>
        <geometry>
          <mesh>
            <scale>1 1 1</scale>
            <uri>models/tiago/tiago_description/meshes/arm/arm_4_collision.dae</uri>
          </mesh>
        </geometry>
        <surface>
          <contact>
            <ode/>
          </contact>
          <friction>
            <ode>
              <mu>0.9</mu>
              <mu2>0.9</mu2>
            </ode>
          </friction>
        </surface>
      </collision>-->
      <visual name='arm_4_link_visual'>
        <pose frame=''>0 0 0 0 -0 0</pose>
        <geometry>
          <mesh>
            <scale>1 1 1</scale>
            <uri>models/tiago/tiago_description/meshes/arm/arm_4.stl</uri>
          </mesh>
        </geometry>
        <material>
          <script>
            <name>Gazebo/DarkGrey</name>
            <uri>file://media/materials/scripts/gazebo.material</uri>
          </script>
        </material>
      </visual>
      <gravity>0</gravity>
      <velocity_decay/>
    </link>

    <joint name='arm_4_joint' type='revolute'>
      <child>arm_4_link</child>
      <parent>arm_3_link</parent>
      <axis>
        <xyz>1 0 -0</xyz>
        <limit>
          <lower>-3.0</lower> <!-- Test 21.06.18: Old Value: -0.392699 -->
          <upper>3.0</upper> <!-- Test 21.06.18: Old Value: 2.35619 -->
          <effort>17.86</effort>
          <velocity>4.58</velocity>
        </limit>
        <dynamics>
          <damping>1</damping>
          <friction>1</friction>
          <spring_reference>0</spring_reference>
          <spring_stiffness>0</spring_stiffness>
        </dynamics>
        <use_parent_model_frame>1</use_parent_model_frame>
      </axis>
      <physics>
        <ode>
          <implicit_spring_damper>1</implicit_spring_damper>
          <cfm_damping>1</cfm_damping>
          <limit>
            <cfm>0</cfm>
            <erp>0.2</erp>
          </limit>
        </ode>
      </physics>
    </joint>

   <link name='arm_5_link'>
      <pose frame=''>0.086050 -0.58450 0.62000 1.5708 0 0</pose>
      <inertial>
        <pose frame=''>3e-05 -0.00028 0.07831 0 -0 0</pose>
        <mass>1.07424</mass>
        <inertia>
          <ixx>0.00168</ixx>
          <ixy>1e-06</ixy>
          <ixz>-1.5e-05</ixz>
          <iyy>0.001603</iyy>
          <iyz>-1.9e-05</iyz>
          <izz>0.000404</izz>
        </inertia>
      </inertial>
      <!--<collision name='arm_5_link_collision'>
        <pose frame=''>0 0 0 0 -0 0</pose>
        <geometry>
          <mesh>
            <scale>1 1 1</scale>
            <uri>models/tiago/tiago_description/meshes/arm/arm_5_collision.dae</uri>
          </mesh>
        </geometry>
        <surface>
          <contact>
            <ode/>
          </contact>
          <friction>
            <ode>
              <mu>0.9</mu>
              <mu2>0.9</mu2>
            </ode>
          </friction>
        </surface>
      </collision>-->
      <visual name='arm_5_link_visual'>
        <pose frame=''>0 0 0 0 -0 0</pose>
        <geometry>
          <mesh>
            <scale>1 1 1</scale>
            <uri>models/tiago/tiago_description/meshes/arm/arm_5.stl</uri>
          </mesh>
        </geometry>
        <material>
          <script>
            <uri>__default__</uri>
            <name>__default__</name>
          </script>
        </material>
      </visual>
      <gravity>0</gravity>
      <velocity_decay/>
    </link>

    <joint name='arm_5_joint' type='revolute'>
      <child>arm_5_link</child>
      <parent>arm_4_link</parent>
      <axis>
        <xyz>0 -1 -0</xyz>
        <limit>
          <lower>-2.0944</lower>
          <upper>2.0944</upper>
          <effort>3</effort>
          <velocity>1.95</velocity>
        </limit>
        <dynamics>
          <damping>1</damping>
          <friction>1</friction>
          <spring_reference>0</spring_reference>
          <spring_stiffness>0</spring_stiffness>
        </dynamics>
        <use_parent_model_frame>1</use_parent_model_frame>
      </axis>
      <physics>
        <ode>
          <implicit_spring_damper>1</implicit_spring_damper>
          <cfm_damping>1</cfm_damping>
          <limit>
            <cfm>0</cfm>
            <erp>0.2</erp>
          </limit>
        </ode>
      </physics>
    </joint>

  <link name='arm_6_link'>
      <pose frame=''>0.086050 -0.73450 0.62000 -0 0 -1.5708</pose>
      <inertial>
        <pose frame=''>0.00531 0.00021 2e-05 0 -0 0</pose>
        <mass>0.28722</mass>
        <inertia>
          <ixx>5.9e-05</ixx>
          <ixy>-0</ixy>
          <ixz>-0</ixz>
          <iyy>0.000106</iyy>
          <iyz>0</iyz>
          <izz>0.000126</izz>
        </inertia>
      </inertial>
      <!--<collision name='arm_6_link_collision'>
        <pose frame=''>0 0 0 0 -0 0</pose>
        <geometry>
          <mesh>
            <scale>1 1 1</scale>
            <uri>models/tiago/tiago_description/meshes/arm/arm_6_collision.dae</uri>
          </mesh>
        </geometry>
        <surface>
          <contact>
            <ode/>
          </contact>
          <friction>
            <ode>
              <mu>0.9</mu>
              <mu2>0.9</mu2>
            </ode>
          </friction>
        </surface>
      </collision>-->
      <visual name='arm_6_link_visual'>
        <pose frame=''>0 0 0 0 -0 0</pose>
        <geometry>
          <mesh>
            <scale>1 1 1</scale>
            <uri>models/tiago/tiago_description/meshes/arm/arm_6.stl</uri>
          </mesh>
        </geometry>
        <material>
          <script>
            <uri>__default__</uri>
            <name>__default__</name>
          </script>
        </material>
      </visual>
      <gravity>0</gravity>
      <velocity_decay/>
    </link>

    <joint name='arm_6_joint' type='revolute'>
      <child>arm_6_link</child>
      <parent>arm_5_link</parent>
      <axis>
        <xyz>0 -0 1</xyz>
        <limit>
          <lower>-3.0</lower> <!-- Test 21.06.18: Old Value: -1.5708 -->
          <upper>1.5708</upper>
          <effort>6.6</effort>
          <velocity>1.76</velocity>
        </limit>
        <dynamics>
          <damping>1</damping>
          <friction>1</friction>
          <spring_reference>0</spring_reference>
          <spring_stiffness>0</spring_stiffness>
        </dynamics>
        <use_parent_model_frame>1</use_parent_model_frame>
      </axis>
      <physics>
        <ode>
          <implicit_spring_damper>1</implicit_spring_damper>
          <cfm_damping>1</cfm_damping>
          <limit>
            <cfm>0</cfm>
            <erp>0.2</erp>
          </limit>
        </ode>
      </physics>
    </joint>

  <link name='arm_7_link'>
      <pose frame=''>0.086050 -0.73450 0.62000 1.5708 1.5708 0</pose>
      <inertial>
        <pose frame=''>-0.000222 0.00019 0.078363 0 -0 0</pose>
        <mass>0.76211</mass>
        <inertia>
          <ixx>0.00139863</ixx>
          <ixy>4.50179e-05</ixy>
          <ixz>2.23503e-06</ixz>
          <iyy>0.00106617</iyy>
          <iyz>-3.26422e-06</iyz>
          <izz>0.000687486</izz>
        </inertia>
      </inertial>
      <!--<collision name='arm_7_link_fixed_joint_lump__arm_tool_link_collision'>
        <pose frame=''>-0 0 0.047 0 -0 -1.5708</pose>
        <geometry>
          <cylinder>
            <length>0.005</length>
            <radius>0.005</radius>
          </cylinder>
        </geometry>
      </collision>
      <collision name='arm_7_link_fixed_joint_lump__gripper_link_collision_1'>
        <pose frame=''>-0 0 0.056 3.14159 -0 -1.5708</pose>
        <geometry>
          <mesh>
            <scale>1 1 1</scale>
            <uri>models/tiago/pal_gripper_description/meshes/gripper_link_collision.stl</uri>
          </mesh>
        </geometry>
        <surface>
          <contact>
            <ode/>
          </contact>
          <friction>
            <ode/>
          </friction>
        </surface>
      </collision>-->
      <visual name='arm_7_link_fixed_joint_lump__arm_tool_link_visual'>
        <pose frame=''>-0 0 0.047 0 -0 -1.5708</pose>
        <geometry>
          <cylinder>
            <length>0.005</length>
            <radius>0.005</radius>
          </cylinder>
        </geometry>
      </visual>
      <visual name='arm_7_link_fixed_joint_lump__gripper_link_visual_1'>
        <pose frame=''>-0 0 0.056 3.14159 -0 -1.5708</pose>
        <geometry>
          <mesh>
            <scale>1 1 1</scale>
            <uri>models/tiago/pal_gripper_description/meshes/gripper_link.stl</uri>
          </mesh>
        </geometry>
        <material>
          <script>
            <name>Gazebo/White</name>
            <uri>file://media/materials/scripts/gazebo.material</uri>
          </script>
        </material>
      </visual>
      <velocity_decay/>
      <gravity>0</gravity>
      <velocity_decay/>
    </link>

    <joint name='arm_7_joint' type='revolute'>
      <child>arm_7_link</child>
      <parent>arm_6_link</parent>
      <axis>
        <xyz>0 -1 -0</xyz>
        <limit>
          <lower>-2.0944</lower>
          <upper>2.0944</upper>
          <effort>6.6</effort>
          <velocity>1.76</velocity>
        </limit>
        <dynamics>
          <damping>1</damping>
          <friction>1</friction>
          <spring_reference>0</spring_reference>
          <spring_stiffness>0</spring_stiffness>
        </dynamics>
        <use_parent_model_frame>1</use_parent_model_frame>
      </axis>
      <physics>
        <provide_feedback>1</provide_feedback>
        <ode>
          <provide_feedback>1</provide_feedback>
          <implicit_spring_damper>1</implicit_spring_damper>
          <cfm_damping>1</cfm_damping>
          <limit>
            <cfm>0</cfm>
            <erp>0.2</erp>
          </limit>
        </ode>
      </physics>
    </joint>

    <link name='gripper_left_finger_link'>
	  <pose frame=''>0.037050 -0.78450 0.62 1.57079 3.1416 3.14159</pose>
      <inertial>
        <pose frame=''>-0.00447 0.010766 -0.121013 0 -0 0</pose>
        <mass>0.10998</mass>
        <inertia>
          <ixx>0.000232</ixx>
          <ixy>-5e-06</ixy>
          <ixz>-3.2e-05</ixz>
          <iyy>0.000224</iyy>
          <iyz>3.6e-05</iyz>
          <izz>2.9e-05</izz>
        </inertia>
      </inertial>
      <!--<collision name='gripper_left_finger_link_collision'>
        <pose frame=''>-0.005 0 -0.165 0 -0 3.1415</pose>
        <geometry>
          <box>
            <size>0.01 0.05 0.11</size>
          </box>
        </geometry>
        <surface>
          <contact>
            <ode>
              <kp>1e+06</kp>
              <kd>1</kd>
              <max_vel>1</max_vel>
              <min_depth>0.1</min_depth>
            </ode>
          </contact>
          <friction>
            <ode>
              <mu>1</mu>
              <mu2>1</mu2>
              <fdir1>0 0 0</fdir1>
            </ode>
          </friction>
        </surface>
      </collision>-->
      <visual name='gripper_left_finger_link_visual'>
        <pose frame=''>0 0 0 0 -0 3.1415</pose>
        <geometry>
          <mesh>
            <scale>1 1 1</scale>
            <uri>models/tiago/pal_gripper_description/meshes/gripper_finger_link.stl</uri>
          </mesh>
        </geometry>
        <material>
          <script>
            <name>Gazebo/Black</name>
            <uri>file://media/materials/scripts/gazebo.material</uri>
          </script>
        </material>
      </visual>
      <velocity_decay/>
      <gravity>0</gravity>
      <velocity_decay/>
    </link>

    <joint name='gripper_left_finger_joint' type='prismatic'>
      <child>gripper_left_finger_link</child>
      <parent>arm_7_link</parent>
      <axis>
        <xyz>1 0 0</xyz>
        <limit>
          <lower>0</lower>
          <upper>0.045</upper>
          <effort>16</effort>
          <velocity>0.05</velocity>
        </limit>
        <dynamics>
          <damping>80</damping>
          <friction>0</friction>
          <spring_reference>0</spring_reference>
          <spring_stiffness>0</spring_stiffness>
        </dynamics>
        <use_parent_model_frame>1</use_parent_model_frame>
      </axis>
      <physics>
        <provide_feedback>1</provide_feedback>
        <ode>
          <provide_feedback>1</provide_feedback>
          <implicit_spring_damper>1</implicit_spring_damper>
          <cfm_damping>1</cfm_damping>
          <limit>
            <cfm>0</cfm>
            <erp>0.2</erp>
          </limit>
        </ode>
      </physics>
    </joint>

    <link name='gripper_right_finger_link'>
      <pose frame=''>0.13505 -0.78450 0.62 1.57079 3.1416 3.14159</pose>
      <inertial>
        <pose frame=''>-0.00447 0.010766 -0.121013 0 -0 0</pose>
        <mass>0.10998</mass>
        <inertia>
          <ixx>0.000232</ixx>
          <ixy>-5e-06</ixy>
          <ixz>-3.2e-05</ixz>
          <iyy>0.000224</iyy>
          <iyz>3.6e-05</iyz>
          <izz>2.9e-05</izz>
        </inertia>
      </inertial>
      <!--<collision name='gripper_right_finger_link_collision'>
        <pose frame=''>0.005 0 -0.165 0 -0 3.1415</pose>
        <geometry>
          <box>
            <size>0.01 0.05 0.11</size>
          </box>
        </geometry>
        <surface>
          <contact>
            <ode>
              <kp>1e+06</kp>
              <kd>1</kd>
              <max_vel>1</max_vel>
              <min_depth>0.1</min_depth>
            </ode>
          </contact>
          <friction>
            <ode>
              <mu>1</mu>
              <mu2>1</mu2>
              <fdir1>0 0 0</fdir1>
            </ode>
          </friction>
        </surface>
      </collision>-->
      <visual name='gripper_right_finger_link_visual'>
        <pose frame=''>0 0 0 0 -0 3.1415</pose>
        <geometry>
          <mesh>
            <scale>-1 -1 1</scale>
            <uri>models/tiago/pal_gripper_description/meshes/gripper_finger_link.stl</uri>
          </mesh>
        </geometry>
        <material>
          <script>
            <name>Gazebo/Black</name>
            <uri>file://media/materials/scripts/gazebo.material</uri>
          </script>
        </material>
      </visual>
      <velocity_decay/>
      <gravity>0</gravity>
      <velocity_decay/>
    </link>

    <joint name='gripper_right_finger_joint' type='prismatic'>
      <child>gripper_right_finger_link</child>
      <parent>arm_7_link</parent>
      <axis>
        <xyz>-1 0 0</xyz>
        <limit>
          <lower>0</lower>
          <upper>0.045</upper>
          <effort>16</effort>
          <velocity>0.05</velocity>
        </limit>
        <dynamics>
          <damping>80</damping>
          <friction>0</friction>
          <spring_reference>0</spring_reference>
          <spring_stiffness>0</spring_stiffness>
        </dynamics>
        <use_parent_model_frame>1</use_parent_model_frame>
      </axis>
      <physics>
        <provide_feedback>1</provide_feedback>
        <ode>
          <provide_feedback>1</provide_feedback>
          <implicit_spring_damper>1</implicit_spring_damper>
          <cfm_damping>1</cfm_damping>
          <limit>
            <cfm>0</cfm>
            <erp>0.2</erp>
          </limit>
        </ode>
      </physics>
    </joint>

  </model>
</sdf>
