<sdf version='1.4'>
  <model name='robot'>
    <link name='base_footprint'>
      <pose>0 0 0 0 -0 0</pose>
      <inertial>
        <pose>-0.00983617 -0.0015008 0.21148 0 -0 0</pose>
        <mass>43.4016</mass>
        <inertia>
          <ixx>2.04327</ixx>
          <ixy>0.000744547</ixy>
          <ixz>0.109545</ixz>
          <iyy>2.13173</iyy>
          <iyz>0.0140814</iyz>
          <izz>0.688729</izz>
        </inertia>
      </inertial>
      <collision name='base_footprint_collision_base_antenna_left_link'>
        <pose>-0.201 0.1062 0.3785 0 -0 0</pose>
        <geometry>
          <cylinder>
            <length>0.17</length>
            <radius>0.005</radius>
          </cylinder>
        </geometry>
        <laser_retro>0</laser_retro>
        <surface>
          <contact>
            <ode>
              <kp>1e+08</kp>
              <kd>10</kd>
              <max_vel>10</max_vel>
              <min_depth>0.0005</min_depth>
            </ode>
          </contact>
          <friction>
            <ode>
              <mu>0.1</mu>
              <mu2>0.1</mu2>
              <fdir1>1 0 0</fdir1>
            </ode>
          </friction>
        </surface>
        <surface>
          <contact>
            <ode/>
          </contact>
          <friction>
            <ode/>
          </friction>
        </surface>
      </collision>
      <collision name='base_footprint_collision_base_antenna_right_link'>
        <pose>-0.201 -0.1062 0.3785 0 -0 0</pose>
        <geometry>
          <cylinder>
            <length>0.17</length>
            <radius>0.005</radius>
          </cylinder>
        </geometry>
        <laser_retro>0</laser_retro>
        <surface>
          <contact>
            <ode>
              <kp>1e+08</kp>
              <kd>10</kd>
              <max_vel>10</max_vel>
              <min_depth>0.0005</min_depth>
            </ode>
          </contact>
          <friction>
            <ode>
              <mu>0.1</mu>
              <mu2>0.1</mu2>
              <fdir1>1 0 0</fdir1>
            </ode>
          </friction>
        </surface>
        <surface>
          <contact>
            <ode/>
          </contact>
          <friction>
            <ode/>
          </friction>
        </surface>
      </collision>
      <collision name='base_footprint_collision_base_link'>
        <pose>0 0 0.0985 0 -0 0</pose>
        <geometry>
          <mesh>
            <scale>1 1 1</scale>
            <uri>model://tiago/pmb2_description/meshes/base/base_collision.dae</uri>
          </mesh>
        </geometry>
        <laser_retro>0</laser_retro>
        <surface>
          <contact>
            <ode>
              <kp>1e+08</kp>
              <kd>10</kd>
              <max_vel>10</max_vel>
              <min_depth>0.0005</min_depth>
            </ode>
          </contact>
          <friction>
            <ode>
              <mu>0.1</mu>
              <mu2>0.1</mu2>
              <fdir1>1 0 0</fdir1>
            </ode>
          </friction>
        </surface>
        <surface>
          <contact>
            <ode/>
          </contact>
          <friction>
            <ode/>
          </friction>
        </surface>
      </collision>
      <collision name='base_footprint_collision_torso_fixed_column_link'>
        <pose>-0.062 0 0.5685 0 -0 0</pose>
        <geometry>
          <box>
            <size>0.23 0.23 0.55</size>
          </box>
        </geometry>
        <laser_retro>0</laser_retro>
        <surface>
          <contact>
            <ode>
              <kp>1e+08</kp>
              <kd>10</kd>
              <max_vel>10</max_vel>
              <min_depth>0.0005</min_depth>
            </ode>
          </contact>
          <friction>
            <ode>
              <mu>0.1</mu>
              <mu2>0.1</mu2>
              <fdir1>1 0 0</fdir1>
            </ode>
          </friction>
        </surface>
        <surface>
          <contact>
            <ode/>
          </contact>
          <friction>
            <ode/>
          </friction>
        </surface>
      </collision>
      <collision name='base_footprint_collision_torso_fixed_link'>
        <pose>0.023 0 0.3115 0 -0 0</pose>
        <geometry>
          <box>
            <size>0.4 0.25 0.04</size>
          </box>
        </geometry>
        <laser_retro>0</laser_retro>
        <surface>
          <contact>
            <ode>
              <kp>1e+08</kp>
              <kd>10</kd>
              <max_vel>10</max_vel>
              <min_depth>0.0005</min_depth>
            </ode>
          </contact>
          <friction>
            <ode>
              <mu>0.1</mu>
              <mu2>0.1</mu2>
              <fdir1>1 0 0</fdir1>
            </ode>
          </friction>
        </surface>
      </collision>
      <collision name='base_footprint_collision_torso_fixed_link_1'>
        <pose>-0.062 0 0.3415 0 -0 0</pose>
        <geometry>
          <box>
            <size>0.25 0.25 0.1</size>
          </box>
        </geometry>
        <laser_retro>0</laser_retro>
        <surface>
          <contact>
            <ode>
              <kp>1e+08</kp>
              <kd>10</kd>
              <max_vel>10</max_vel>
              <min_depth>0.0005</min_depth>
            </ode>
          </contact>
          <friction>
            <ode>
              <mu>0.1</mu>
              <mu2>0.1</mu2>
              <fdir1>1 0 0</fdir1>
            </ode>
          </friction>
        </surface>
      </collision>
      <visual name='base_footprint_visual_base_antenna_left_link'>
        <pose>-0.201 0.1062 0.2935 0 -0 0</pose>
        <geometry>
          <mesh>
            <scale>1 1 1</scale>
            <uri>model://tiago/pmb2_description/meshes/objects/antenna.stl</uri>
          </mesh>
        </geometry>
        <material>
          <script>
            <name>Gazebo/Black</name>
            <uri>__default__</uri>
          </script>
        </material>
      </visual>
      <visual name='base_footprint_visual_base_antenna_right_link'>
        <pose>-0.201 -0.1062 0.2935 0 -0 0</pose>
        <geometry>
          <mesh>
            <scale>1 1 1</scale>
            <uri>model://tiago/pmb2_description/meshes/objects/antenna.stl</uri>
          </mesh>
        </geometry>
        <material>
          <script>
            <name>Gazebo/Black</name>
            <uri>__default__</uri>
          </script>
        </material>
      </visual>
      <visual name='base_footprint_visual_base_cover_link'>
        <pose>0 0 0.13 0 -0 0</pose>
        <geometry>
          <mesh>
            <scale>1 1 1</scale>
            <uri>model://tiago/pmb2_description/meshes/base/base_ring.stl</uri>
          </mesh>
        </geometry>
        <material>
          <script>
            <name>Gazebo/Orange</name>
            <uri>__default__</uri>
          </script>
        </material>
      </visual>
      <visual name='base_footprint_visual_base_laser_link'>
        <pose>0.202 0 0.0945 0 -0 0</pose>
        <geometry>
          <mesh>
            <scale>1 1 1</scale>
            <uri>model://tiago/pmb2_description/meshes/sensors/sick_tim551.stl</uri>
          </mesh>
        </geometry>
        <material>
          <script>
            <name>Gazebo/DarkGrey</name>
            <uri>__default__</uri>
          </script>
        </material>
      </visual>
      <visual name='base_footprint_visual_base_link'>
        <pose>0 0 0.0985 0 -0 0</pose>
        <geometry>
          <mesh>
            <scale>1 1 1</scale>
            <uri>model://tiago/pmb2_description/meshes/base/base.stl</uri>
          </mesh>
        </geometry>
        <material>
          <script>
            <name>Gazebo/White</name>
            <uri>__default__</uri>
          </script>
        </material>
      </visual>
      <visual name='base_footprint_visual_base_sonar_01_link'>
        <pose>-0.183 -0.183 0.2715 0 -0 -2.35619</pose>
        <geometry>
          <mesh>
            <scale>1 1 1</scale>
            <uri>model://tiago/pmb2_description/meshes/sensors/srf05.stl</uri>
          </mesh>
        </geometry>
        <material>
          <script>
            <name>Gazebo/DarkGrey</name>
            <uri>__default__</uri>
          </script>
        </material>
      </visual>
      <visual name='base_footprint_visual_base_sonar_02_link'>
        <pose>-0.259 0 0.2715 0 -0 -3.14159</pose>
        <geometry>
          <mesh>
            <scale>1 1 1</scale>
            <uri>model://tiago/pmb2_description/meshes/sensors/srf05.stl</uri>
          </mesh>
        </geometry>
        <material>
          <script>
            <name>Gazebo/DarkGrey</name>
            <uri>__default__</uri>
          </script>
        </material>
      </visual>
      <visual name='base_footprint_visual_base_sonar_03_link'>
        <pose>-0.183 0.183 0.2715 0 -0 2.35619</pose>
        <geometry>
          <mesh>
            <scale>1 1 1</scale>
            <uri>model://tiago/pmb2_description/meshes/sensors/srf05.stl</uri>
          </mesh>
        </geometry>
        <material>
          <script>
            <name>Gazebo/DarkGrey</name>
            <uri>__default__</uri>
          </script>
        </material>
      </visual>
      <visual name='base_footprint_visual_caster_back_left_1_link'>
        <pose>-0.1735 0.102 0.065 0 -0 0</pose>
        <geometry>
          <mesh>
            <scale>1 1 1</scale>
            <uri>model://tiago/pmb2_description/meshes/wheels/caster_1.stl</uri>
          </mesh>
        </geometry>
      </visual>
      <visual name='base_footprint_visual_caster_back_left_2_link'>
        <pose>-0.1895 0.102 0.025 -1.5708 0 0</pose>
        <geometry>
          <mesh>
            <scale>1 1 1</scale>
            <uri>model://tiago/pmb2_description/meshes/wheels/caster_2.stl</uri>
          </mesh>
        </geometry>
      </visual>
      <visual name='base_footprint_visual_caster_back_right_1_link'>
        <pose>-0.1735 -0.102 0.065 0 -0 0</pose>
        <geometry>
          <mesh>
            <scale>1 1 1</scale>
            <uri>model://tiago/pmb2_description/meshes/wheels/caster_1.stl</uri>
          </mesh>
        </geometry>
      </visual>
      <visual name='base_footprint_visual_caster_back_right_2_link'>
        <pose>-0.1895 -0.102 0.025 -1.5708 0 0</pose>
        <geometry>
          <mesh>
            <scale>1 1 1</scale>
            <uri>model://tiago/pmb2_description/meshes/wheels/caster_2.stl</uri>
          </mesh>
        </geometry>
      </visual>
      <visual name='base_footprint_visual_caster_front_left_1_link'>
        <pose>0.1695 0.102 0.065 0 -0 0</pose>
        <geometry>
          <mesh>
            <scale>1 1 1</scale>
            <uri>model://tiago/pmb2_description/meshes/wheels/caster_1.stl</uri>
          </mesh>
        </geometry>
      </visual>
      <visual name='base_footprint_visual_caster_front_left_2_link'>
        <pose>0.1535 0.102 0.025 -1.5708 0 0</pose>
        <geometry>
          <mesh>
            <scale>1 1 1</scale>
            <uri>model://tiago/pmb2_description/meshes/wheels/caster_2.stl</uri>
          </mesh>
        </geometry>
      </visual>
      <visual name='base_footprint_visual_caster_front_right_1_link'>
        <pose>0.1695 -0.102 0.065 0 -0 0</pose>
        <geometry>
          <mesh>
            <scale>1 1 1</scale>
            <uri>model://tiago/pmb2_description/meshes/wheels/caster_1.stl</uri>
          </mesh>
        </geometry>
      </visual>
      <visual name='base_footprint_visual_caster_front_right_2_link'>
        <pose>0.1535 -0.102 0.025 -1.5708 0 0</pose>
        <geometry>
          <mesh>
            <scale>1 1 1</scale>
            <uri>model://tiago/pmb2_description/meshes/wheels/caster_2.stl</uri>
          </mesh>
        </geometry>
      </visual>
      <visual name='base_footprint_visual_torso_fixed_column_link'>
        <pose>-0.062 0 0.5685 0 -0 0</pose>
        <geometry>
          <box>
            <size>0.18 0.2 0.55</size>
          </box>
        </geometry>
        <material>
          <script>
            <name>Gazebo/DarkGrey</name>
            <uri>__default__</uri>
          </script>
        </material>
      </visual>
      <visual name='base_footprint_visual_torso_fixed_link'>
        <pose>-0.062 0 0.2915 0 -0 0</pose>
        <geometry>
          <mesh>
            <scale>1 1 1</scale>
            <uri>model://tiago/tiago_description/meshes/torso/torso_fix.stl</uri>
          </mesh>
        </geometry>
      </visual>
      <velocity_decay>
        <linear>0</linear>
        <angular>0</angular>
      </velocity_decay>
      <velocity_decay>
        <linear>0</linear>
        <angular>0</angular>
      </velocity_decay>
      <velocity_decay>
        <linear>0</linear>
        <angular>0</angular>
      </velocity_decay>
      <velocity_decay>
        <linear>0</linear>
        <angular>0</angular>
      </velocity_decay>
      <velocity_decay>
        <linear>0</linear>
        <angular>0</angular>
      </velocity_decay>

      <sensor name='imu_sensor' type='imu'>
        <always_on>1</always_on>
        <update_rate>1000</update_rate>
        <imu>
          <noise>
            <type>gaussian</type>
            <rate>
              <mean>0</mean>
              <stddev>0.0002</stddev>
              <bias_mean>7.5e-06</bias_mean>
              <bias_stddev>8e-07</bias_stddev>
            </rate>
            <accel>
              <mean>0</mean>
              <stddev>0.017</stddev>
              <bias_mean>0.1</bias_mean>
              <bias_stddev>0.001</bias_stddev>
            </accel>
          </noise>
        </imu>
        <pose>0.10171 0 0.21132 0 0 -1.5708</pose>
      </sensor>

      <velocity_decay>
        <linear>0</linear>
        <angular>0</angular>
      </velocity_decay>

      <sensor name='base_imu_sensor' type='imu'>
        <always_on>1</always_on>
        <update_rate>100</update_rate>
        <imu>
          <noise>
            <type>gaussian</type>
            <rate>
              <mean>0</mean>
              <stddev>0.0002</stddev>
              <bias_mean>7.5e-06</bias_mean>
              <bias_stddev>8e-07</bias_stddev>
            </rate>
            <accel>
              <mean>0</mean>
              <stddev>0.017</stddev>
              <bias_mean>0.1</bias_mean>
              <bias_stddev>0.001</bias_stddev>
            </accel>
          </noise>
        </imu>
        <pose>0.10171 0 0.21132 0 0 -1.5708</pose>
      </sensor>

      <velocity_decay>
        <linear>0</linear>
        <angular>0</angular>
      </velocity_decay>
      <sensor name='base_laser' type='ray'>
        <update_rate>10</update_rate>
        <visualize>1</visualize>
        <ray>
          <scan>
            <horizontal>
              <samples>640</samples>
              <resolution>1</resolution>
              <min_angle>-1.91986</min_angle>
              <max_angle>1.91986</max_angle>
            </horizontal>
          </scan>
          <range>
            <min>0.05</min>
            <max>10</max>
            <resolution>0.001</resolution>
          </range>
        </ray>
        <pose>0.202 0 0.0945 0 -0 0</pose>
      	<!-- Attach the plugin to this model -->
		<!--      	
		<plugin name="laserScanPlugin" filename="liblaserScanPlugin.so">
      	</plugin>
		-->
	  </sensor>
      <velocity_decay>
        <linear>0</linear>
        <angular>0</angular>
      </velocity_decay>
      <sensor name='base_sonar_01' type='ray'>
        <update_rate>5</update_rate>
        <visualize>0</visualize>
        <ray>
          <scan>
            <horizontal>
              <samples>5</samples>
              <resolution>1</resolution>
              <min_angle>-0.25</min_angle>
              <max_angle>0.25</max_angle>
            </horizontal>
            <vertical>
              <samples>5</samples>
              <resolution>1</resolution>
              <min_angle>-0.25</min_angle>
              <max_angle>0.25</max_angle>
            </vertical>
          </scan>
          <range>
            <min>0.02</min>
            <max>2</max>
            <resolution>0.01</resolution>
          </range>
        </ray>
        <pose>-0.183 -0.183 0.2715 0 -0 -2.35619</pose>
      </sensor>
      <velocity_decay>
        <linear>0</linear>
        <angular>0</angular>
      </velocity_decay>
      <sensor name='base_sonar_02' type='ray'>
        <update_rate>5</update_rate>
        <visualize>0</visualize>
        <ray>
          <scan>
            <horizontal>
              <samples>5</samples>
              <resolution>1</resolution>
              <min_angle>-0.25</min_angle>
              <max_angle>0.25</max_angle>
            </horizontal>
            <vertical>
              <samples>5</samples>
              <resolution>1</resolution>
              <min_angle>-0.25</min_angle>
              <max_angle>0.25</max_angle>
            </vertical>
          </scan>
          <range>
            <min>0.02</min>
            <max>2</max>
            <resolution>0.01</resolution>
          </range>
        </ray>
        <pose>-0.259 0 0.2715 0 -0 -3.14159</pose>
      </sensor>
      <velocity_decay>
        <linear>0</linear>
        <angular>0</angular>
      </velocity_decay>
      <sensor name='base_sonar_03' type='ray'>
        <update_rate>5</update_rate>
        <visualize>0</visualize>
        <ray>
          <scan>
            <horizontal>
              <samples>5</samples>
              <resolution>1</resolution>
              <min_angle>-0.25</min_angle>
              <max_angle>0.25</max_angle>
            </horizontal>
            <vertical>
              <samples>5</samples>
              <resolution>1</resolution>
              <min_angle>-0.25</min_angle>
              <max_angle>0.25</max_angle>
            </vertical>
          </scan>
          <range>
            <min>0.02</min>
            <max>2</max>
            <resolution>0.01</resolution>
          </range>
        </ray>
        <pose>-0.183 0.183 0.2715 0 -0 2.35619</pose>
      </sensor>
      <velocity_decay>
        <linear>0</linear>
        <angular>0</angular>
      </velocity_decay>
      <gravity>1</gravity>
      <velocity_decay>
        <linear>0</linear>
        <angular>0</angular>
      </velocity_decay>
      <self_collide>0</self_collide>
    </link>
    <link name='torso_lift_link'>
      <pose>-0.062 0 0.8785 0 -0 0</pose>
      <inertial>
        <pose>0.04361 -0.00116 -0.17334 0 -0 0</pose>
        <mass>6.93198</mass>
        <inertia>
          <ixx>0.24487</ixx>
          <ixy>-0.001456</ixy>
          <ixz>-0.009742</ixz>
          <iyy>0.249269</iyy>
          <iyz>0.008281</iyz>
          <izz>0.090395</izz>
        </inertia>
      </inertial>
      <collision name='torso_lift_link_collision'>
        <pose>0 0 0 0 -0 0</pose>
        <geometry>
          <mesh>
            <scale>1 1 1</scale>
            <uri>model://tiago/tiago_description/meshes/torso/torso_lift_collision.dae</uri>
          </mesh>
        </geometry>
      </collision>
      <visual name='torso_lift_link_visual'>
        <pose>0 0 0 0 -0 0</pose>
        <geometry>
          <mesh>
            <scale>1 1 1</scale>
            <uri>model://tiago/tiago_description/meshes/torso/torso_lift_with_arm.stl</uri>
          </mesh>
        </geometry>
      </visual>
      <velocity_decay>
        <linear>0</linear>
        <angular>0</angular>
      </velocity_decay>
    </link>
    <joint name='torso_lift_joint' type='prismatic'>
      <child>torso_lift_link</child>
      <parent>base_footprint</parent>
      <axis>
        <xyz>0 0 1</xyz>
        <limit>
          <lower>0</lower>
          <upper>0.35</upper>
          <effort>2000</effort>
          <velocity>0.07</velocity>
        </limit>
        <dynamics>
          <damping>1000</damping>
        </dynamics>
      </axis>
    </joint>

    <link name='head_1_link'>
      <pose>0.12 0 0.8785 0 -0 0</pose>
      <inertial>
        <pose>-0.00508 0.00237 0.07229 0 -0 0</pose>
        <mass>0.6222</mass>
        <inertia>
          <ixx>0.001192</ixx>
          <ixy>-7e-06</ixy>
          <ixz>9.6e-05</ixz>
          <iyy>0.001402</iyy>
          <iyz>4e-06</iyz>
          <izz>0.000889</izz>
        </inertia>
      </inertial>
      <collision name='head_1_link_collision'>
        <pose>0 0 0 0 -0 0</pose>
        <geometry>
          <mesh>
            <scale>1 1 1</scale>
            <uri>model://tiago/tiago_description/meshes/head/head_1_collision.dae</uri>
          </mesh>
        </geometry>
        <surface>
          <contact>
            <ode/>
          </contact>
          <friction>
            <ode>
              <mu>0.9</mu>
              <mu2>0.9</mu2>
            </ode>
          </friction>
        </surface>
      </collision>
      <visual name='head_1_link_visual'>
        <pose>0 0 0 0 -0 0</pose>
        <geometry>
          <mesh>
            <scale>1 1 1</scale>
            <uri>model://tiago/tiago_description/meshes/head/head_1.stl</uri>
          </mesh>
        </geometry>
      </visual>
      <!-- Timo: gravity 0, damit Rotation problemlos funktioniert -->
      <gravity>0</gravity>
      <velocity_decay>
        <linear>0</linear>
        <angular>0</angular>
      </velocity_decay>
      <self_collide>0</self_collide>
    </link>
    <joint name='head_1_joint' type='revolute'>
      <child>head_1_link</child>
      <parent>torso_lift_link</parent>
      <axis>
        <xyz>0 0 1</xyz>
        <limit>
          <lower>-1.309</lower>
          <upper>1.309</upper>
          <effort>5.197</effort>
          <velocity>3</velocity>
        </limit>
        <dynamics>
          <damping>0.5</damping>
        </dynamics>
      </axis>
      <physics>
        <ode>
          <implicit_spring_damper>1</implicit_spring_damper>
          <cfm_damping>1</cfm_damping>
          <limit>
            <cfm>0</cfm>
            <erp>0.2</erp>
          </limit>
        </ode>
      </physics>
    </joint>
    <link name='head_2_link'>
      <pose>0.125 0 0.9765 1.5708 -0 0</pose>
      <inertial>
        <pose>0.0557879 0.0609773 1.13571e-05 0 -0 0</pose>
        <mass>0.88593</mass>
        <inertia>
          <ixx>0.00476064</ixx>
          <ixy>0.000561581</ixy>
          <ixz>1.2081e-05</ixz>
          <iyy>0.00512284</iyy>
          <iyz>9.40226e-06</iyz>
          <izz>0.00346439</izz>
        </inertia>
      </inertial>
      <collision name='head_2_link_collision'>
        <pose>0 0 0 0 -0 0</pose>
        <geometry>
          <mesh>
            <scale>1 1 1</scale>
            <uri>model://tiago/tiago_description/meshes/head/head_2_collision.dae</uri>
          </mesh>
        </geometry>
      </collision>
      <visual name='head_2_link_visual'>
        <pose>0 0 0 0 -0 0</pose>
        <geometry>
          <mesh>
            <scale>1 1 1</scale>
            <uri>model://tiago/tiago_description/meshes/head/head_2.stl</uri>
          </mesh>
        </geometry>
      </visual>
      <!-- Timo: gravity 0, damit Rotation problemlos funktioniert -->
      <gravity>0</gravity>
      <velocity_decay>
        <linear>0</linear>
        <angular>0</angular>
      </velocity_decay>
      <self_collide>0</self_collide>
    </link>

    <joint name='head_2_joint' type='revolute'>
      <child>head_2_link</child>
      <parent>head_1_link</parent>
      <axis>
        <!--<use_parent_model_frame>1</use_parent_model_frame>-->
        <xyz>0 -1 0</xyz>
        <limit>
          <lower>-1.0472</lower>
          <upper>0.785398</upper>
          <effort>2.77</effort>
          <velocity>3</velocity>
        </limit>
        <dynamics>
          <damping>0.5</damping>
        </dynamics>
      </axis>
    </joint>

 	<joint name="xtion_joint" type="fixed">
		<origin rpy="-1.57079632679 0 0" xyz="0.0908 0.08 0"/>
		<pose>0.0908 0.08 0 -1.57079632679 0 0</pose>
		<parent>head_2_link</parent>
		<child>xtion_link</child>
  	</joint>

  	<link name="xtion_link">
		<inertial>
		  <origin rpy="0 0 0" xyz="-0.00936000000 -0.00003000000 -0.00273000000"/>
		  <mass value="0.21970000000"/>
		  <inertia ixx="0.00000429247" ixy="0.00000000000" ixz="0.00000002565" iyy="0.00000008027" iyz="0.00000000000" izz="0.00000427339"/>
		</inertial>
	  <pose>0.25 0 1.05 0 0 0</pose>
      <visual name='xtion_link_visual'>
        <pose>0 0 0 0 -0 0</pose>
        <geometry>
          <mesh>
            <scale>1 1 1</scale>
            <uri>model://tiago/tiago_description/meshes/sensors/xtion_pro_live/xtion_pro_live.dae</uri>
          </mesh>
        </geometry>
      </visual>

     <sensor name='xtion_frame_sensor' type='depth'>
        <always_on>1</always_on>
        <update_rate>30</update_rate>
        <camera name='__default__'>
          <horizontal_fov>1.01229</horizontal_fov>
          <image>
            <format>B8G8R8</format>
            <width>1920</width>
            <height>1080</height>
          </image>
          <clip>
            <near>0.3</near>
            <far>20</far>
          </clip>
        </camera>
        <!--<pose>0.0908 0.08 -0.022 -1.5708 0 0</pose>-->
        <plugin name="DepthCameraPlugin" filename="libDepthCameraPlugin.so">
        
        <distortionK1>0.0</distortionK1>
        <distortionK2>0.0</distortionK2>
        <distortionK3>0.0</distortionK3>
        <distortionT1>0.0</distortionT1>
        <distortionT2>0.0</distortionT2>
        <CxPrime>0.0</CxPrime>
        <Cx>0.0</Cx>
        <Cy>0.0</Cy>
        <focalLength>0.0</focalLength>
        
        </plugin>
      </sensor>
    <!-- Timo: gravity 0, damit Rotation problemlos funktioniert -->
	<gravity>0</gravity>
  	</link>



    <link name='wheel_left_link'>
      <pose>0 0.2022 0.0985 -1.5708 0 0</pose>
      <inertial>
        <pose>0 0 0.00207 0 -0 0</pose>
        <mass>1.82362</mass>
        <inertia>
          <ixx>0.00499743</ixx>
          <ixy>-4.464e-08</ixy>
          <ixz>-2.245e-08</ixz>
          <iyy>0.00499742</iyy>
          <iyz>1.64e-09</iyz>
          <izz>0.0083924</izz>
        </inertia>
      </inertial>
      <collision name='wheel_left_link_collision'>
        <pose>0 0 0 0 -0 0</pose>
        <geometry>
          <cylinder>
            <length>0.04</length>
            <radius>0.0985</radius>
          </cylinder>
        </geometry>
        <surface>
          <contact>
            <ode>
              <kp>1e+06</kp>
              <kd>100</kd>
              <max_vel>1</max_vel>
              <min_depth>0.003</min_depth>
            </ode>
          </contact>
          <friction>
            <ode>
              <mu>1</mu>
              <mu2>1</mu2>
              <fdir1>1 0 0</fdir1>
            </ode>
          </friction>
        </surface>
      </collision>
      <visual name='wheel_left_link_visual'>
        <pose>0 0 0 3.14159 -0 0</pose>
        <geometry>
          <mesh>
            <scale>1 1 1</scale>
            <uri>model://tiago/pmb2_description/meshes/wheels/wheel.stl</uri>
          </mesh>
        </geometry>
        <material>
          <script>
            <name>Gazebo/DarkGrey</name>
            <uri>__default__</uri>
          </script>
        </material>
      </visual>
      <gravity>1</gravity>
      <velocity_decay>
        <linear>0</linear>
        <angular>0</angular>
      </velocity_decay>
      <self_collide>0</self_collide>
    </link>
    <joint name='wheel_left_joint' type='revolute'>
      <child>wheel_left_link</child>
      <parent>base_footprint</parent>
      <axis>
        <xyz>0 1 4.89658e-12</xyz>
        <limit>
          <lower>-1e+16</lower>
          <upper>1e+16</upper>
        </limit>
        <dynamics/>
      </axis>
    </joint>
    <link name='wheel_right_link'>
      <pose>0 -0.2022 0.0985 -1.5708 0 0</pose>
      <inertial>
        <pose>0 0 -0.00207 0 -0 0</pose>
        <mass>1.82362</mass>
        <inertia>
          <ixx>0.00499743</ixx>
          <ixy>4.464e-08</ixy>
          <ixz>-2.245e-08</ixz>
          <iyy>0.00499742</iyy>
          <iyz>-1.64e-09</iyz>
          <izz>0.0083924</izz>
        </inertia>
      </inertial>
      <collision name='wheel_right_link_collision'>
        <pose>0 0 0 0 -0 0</pose>
        <geometry>
          <cylinder>
            <length>0.04</length>
            <radius>0.0985</radius>
          </cylinder>
        </geometry>
        <surface>
          <contact>
            <ode>
              <kp>1e+06</kp>
              <kd>100</kd>
              <max_vel>1</max_vel>
              <min_depth>0.003</min_depth>
            </ode>
          </contact>
          <friction>
            <ode>
              <mu>1</mu>
              <mu2>1</mu2>
              <fdir1>1 0 0</fdir1>
            </ode>
          </friction>
        </surface>
      </collision>
      <visual name='wheel_right_link_visual'>
        <pose>0 0 0 0 -0 0</pose>
        <geometry>
          <mesh>
            <scale>1 1 1</scale>
            <uri>model://tiago/pmb2_description/meshes/wheels/wheel.stl</uri>
          </mesh>
        </geometry>
        <material>
          <script>
            <name>Gazebo/DarkGrey</name>
            <uri>__default__</uri>
          </script>
        </material>
      </visual>
      <gravity>1</gravity>
      <velocity_decay>
        <linear>0</linear>
        <angular>0</angular>
      </velocity_decay>
      <self_collide>0</self_collide>
    </link>
    <joint name='wheel_right_joint' type='revolute'>
      <child>wheel_right_link</child>
      <parent>base_footprint</parent>
      <axis>
        <xyz>0 1 4.89658e-12</xyz>
        <limit>
          <lower>-1e+16</lower>
          <upper>1e+16</upper>
        </limit>
        <dynamics/>
      </axis>
    </joint>


    <link name='arm_1_link'>
      <pose frame=''>0.071050 0.014000 0.65100 0 0 -1.5708</pose>
      <inertial>
        <pose frame=''>0.08169 0.01822 -0.01884 0 -0 0</pose>
        <mass>2.31325</mass>
        <inertia>
          <ixx>0.002694</ixx>
          <ixy>0.001157</ixy>
          <ixz>-0.001423</ixz>
          <iyy>0.007041</iyy>
          <iyz>-0.000312</iyz>
          <izz>0.007312</izz>
        </inertia>
      </inertial>
      <collision name='arm_1_link_collision'>
        <pose frame=''>0 0 0 0 -0 0</pose>
        <geometry>
          <mesh>
            <scale>1 1 1</scale>
            <uri>model://tiago/tiago_description/meshes/arm/arm_1_collision.dae</uri>
          </mesh>
        </geometry>
        <surface>
          <contact>
            <ode/>
          </contact>
          <friction>
            <ode>
              <mu>0.9</mu>
              <mu2>0.9</mu2>
            </ode>
          </friction>
        </surface>
      </collision>
      <visual name='arm_1_link_visual'>
        <pose frame=''>0 0 0 0 -0 0</pose>
        <geometry>
          <mesh>
            <scale>1 1 1</scale>
            <uri>model://tiago/tiago_description/meshes/arm/arm_1.stl</uri>
          </mesh>
        </geometry>
        <material>
          <script>
            <name>Gazebo/DarkGrey</name>
            <uri>file://media/materials/scripts/gazebo.material</uri>
          </script>
        </material>
      </visual>
      <velocity_decay/>
      <gravity>0</gravity>
      <velocity_decay/>
    </link>
    <joint name='arm_1_joint' type='revolute'>
      <child>arm_1_link</child>
      <parent>torso_lift_link</parent>
      <axis>
        <xyz>0 0 1</xyz>
        <limit>
          <lower>0</lower>
          <upper>2.74889</upper>
          <effort>39</effort>
          <velocity>2.7</velocity>
        </limit>
        <dynamics>
          <damping>1</damping>
          <friction>1</friction>
          <spring_reference>0</spring_reference>
          <spring_stiffness>0</spring_stiffness>
        </dynamics>
        <use_parent_model_frame>1</use_parent_model_frame>
      </axis>
      <physics>
        <ode>
          <implicit_spring_damper>1</implicit_spring_damper>
          <cfm_damping>1</cfm_damping>
          <limit>
            <cfm>0</cfm>
            <erp>0.2</erp>
          </limit>
        </ode>
      </physics>
    </joint>
    <link name='arm_2_link'>
      <pose frame=''>0.087550 -0.111 0.62000 1.5708 0 -1.5708</pose>
      <inertial>
        <pose frame=''>-0.03609 -6e-05 0.01649 0 -0 0</pose>
        <mass>1.10224</mass>
        <inertia>
          <ixx>0.001146</ixx>
          <ixy>1e-06</ixy>
          <ixz>0.000435</ixz>
          <iyy>0.002182</iyy>
          <iyz>-1e-06</iyz>
          <izz>0.002373</izz>
        </inertia>
      </inertial>
      <collision name='arm_2_link_collision'>
        <pose frame=''>0 0 0 0 -0 0</pose>
        <geometry>
          <mesh>
            <scale>1 1 1</scale>
            <uri>model://tiago/tiago_description/meshes/arm/arm_2_collision.dae</uri>
          </mesh>
        </geometry>
        <surface>
          <contact>
            <ode/>
          </contact>
          <friction>
            <ode>
              <mu>0.9</mu>
              <mu2>0.9</mu2>
            </ode>
          </friction>
        </surface>
      </collision>
      <visual name='arm_2_link_visual'>
        <pose frame=''>0 0 0 0 -0 0</pose>
        <geometry>
          <mesh>
            <scale>1 1 1</scale>
            <uri>model://tiago/tiago_description/meshes/arm/arm_2.stl</uri>
          </mesh>
        </geometry>
        <material>
          <script>
            <name>Gazebo/DarkGrey</name>
            <uri>file://media/materials/scripts/gazebo.material</uri>
          </script>
        </material>
      </visual>
      <gravity>0</gravity>
      <velocity_decay/>
    </link>
    <joint name='arm_2_joint' type='revolute'>
      <child>arm_2_link</child>
      <parent>arm_1_link</parent>
      <axis>
        <xyz>-1 -0 0</xyz>
        <limit>
          <lower>-1.5708</lower>
          <upper>1.19083</upper>
          <effort>39</effort>
          <velocity>3.66</velocity>
        </limit>
        <dynamics>
          <damping>1</damping>
          <friction>1</friction>
          <spring_reference>0</spring_reference>
          <spring_stiffness>0</spring_stiffness>
        </dynamics>
        <use_parent_model_frame>1</use_parent_model_frame>
      </axis>
      <physics>
        <ode>
          <implicit_spring_damper>1</implicit_spring_damper>
          <cfm_damping>1</cfm_damping>
          <limit>
            <cfm>0</cfm>
            <erp>0.2</erp>
          </limit>
        </ode>
      </physics>
    </joint>
    <link name='arm_3_link'>
      <pose frame=''>0.086050 -0.20050 0.62000 1.57079 -1.57079 3.14159</pose>
      <inertial>
        <pose frame=''>0.00752 0.00244 0.12957 0 -0 0</pose>
        <mass>2.4246</mass>
        <inertia>
          <ixx>0.014418</ixx>
          <ixy>8.4e-05</ixy>
          <ixz>0.001143</ixz>
          <iyy>0.014788</iyy>
          <iyz>0.000642</iyz>
          <izz>0.00256</izz>
        </inertia>
      </inertial>
      <collision name='arm_3_link_collision'>
        <pose frame=''>0 0 0 0 -0 0</pose>
        <geometry>
          <mesh>
            <scale>1 1 1</scale>
            <uri>model://tiago/tiago_description/meshes/arm/arm_3_collision.dae</uri>
          </mesh>
        </geometry>
        <surface>
          <contact>
            <ode/>
          </contact>
          <friction>
            <ode>
              <mu>0.9</mu>
              <mu2>0.9</mu2>
            </ode>
          </friction>
        </surface>
      </collision>
      <visual name='arm_3_link_visual'>
        <pose frame=''>0 0 0 0 -0 0</pose>
        <geometry>
          <mesh>
            <scale>1 1 1</scale>
            <uri>model://tiago/tiago_description/meshes/arm/arm_3.stl</uri>
          </mesh>
        </geometry>
        <material>
          <script>
            <name>Gazebo/DarkGrey</name>
            <uri>file://media/materials/scripts/gazebo.material</uri>
          </script>
        </material>
      </visual>
      <gravity>0</gravity>
      <velocity_decay/>
    </link>
    <joint name='arm_3_joint' type='revolute'>
      <child>arm_3_link</child>
      <parent>arm_2_link</parent>
      <axis>
        <xyz>-0 1 0</xyz>
        <limit>
          <lower>-3.53429</lower>
          <upper>1.9708</upper>
          <effort>17.86</effort>
          <velocity>4.58</velocity>
        </limit>
        <dynamics>
          <damping>1</damping>
          <friction>1</friction>
          <spring_reference>0</spring_reference>
          <spring_stiffness>0</spring_stiffness>
        </dynamics>
        <use_parent_model_frame>1</use_parent_model_frame>
      </axis>
      <physics>
        <ode>
          <implicit_spring_damper>1</implicit_spring_damper>
          <cfm_damping>1</cfm_damping>
          <limit>
            <cfm>0</cfm>
            <erp>0.2</erp>
          </limit>
        </ode>
      </physics>
    </joint>

   <link name='arm_4_link'>
      <pose frame=''>0.059050 -0.42250 0.60000 1.5708 -0 1.5708</pose>
      <inertial>
        <pose frame=''>0.07426 -0.01306 0.01549 0 -0 0</pose>
        <mass>1.45429</mass>
        <inertia>
          <ixx>0.001953</ixx>
          <ixy>-0.000596</ixy>
          <ixz>0.00088</ixz>
          <iyy>0.007097</iyy>
          <iyz>-0.000171</iyz>
          <izz>0.007405</izz>
        </inertia>
      </inertial>
      <collision name='arm_4_link_collision'>
        <pose frame=''>0 0 0 0 -0 0</pose>
        <geometry>
          <mesh>
            <scale>1 1 1</scale>
            <uri>model://tiago/tiago_description/meshes/arm/arm_4_collision.dae</uri>
          </mesh>
        </geometry>
        <surface>
          <contact>
            <ode/>
          </contact>
          <friction>
            <ode>
              <mu>0.9</mu>
              <mu2>0.9</mu2>
            </ode>
          </friction>
        </surface>
      </collision>
      <visual name='arm_4_link_visual'>
        <pose frame=''>0 0 0 0 -0 0</pose>
        <geometry>
          <mesh>
            <scale>1 1 1</scale>
            <uri>model://tiago/tiago_description/meshes/arm/arm_4.stl</uri>
          </mesh>
        </geometry>
        <material>
          <script>
            <name>Gazebo/DarkGrey</name>
            <uri>file://media/materials/scripts/gazebo.material</uri>
          </script>
        </material>
      </visual>
      <gravity>0</gravity>
      <velocity_decay/>
    </link>
    <joint name='arm_4_joint' type='revolute'>
      <child>arm_4_link</child>
      <parent>arm_3_link</parent>
      <axis>
        <xyz>1 0 -0</xyz>
        <limit>
          <lower>-3.0</lower> <!-- Test 21.06.18: Old Value: -0.392699 -->
          <upper>3.0</upper> <!-- Test 21.06.18: Old Value: 2.35619 -->
          <effort>17.86</effort>
          <velocity>4.58</velocity>
        </limit>
        <dynamics>
          <damping>1</damping>
          <friction>1</friction>
          <spring_reference>0</spring_reference>
          <spring_stiffness>0</spring_stiffness>
        </dynamics>
        <use_parent_model_frame>1</use_parent_model_frame>
      </axis>
      <physics>
        <ode>
          <implicit_spring_damper>1</implicit_spring_damper>
          <cfm_damping>1</cfm_damping>
          <limit>
            <cfm>0</cfm>
            <erp>0.2</erp>
          </limit>
        </ode>
      </physics>
    </joint>

   <link name='arm_5_link'>
      <pose frame=''>0.086050 -0.58450 0.62000 1.5708 0 0</pose>
      <inertial>
        <pose frame=''>3e-05 -0.00028 0.07831 0 -0 0</pose>
        <mass>1.07424</mass>
        <inertia>
          <ixx>0.00168</ixx>
          <ixy>1e-06</ixy>
          <ixz>-1.5e-05</ixz>
          <iyy>0.001603</iyy>
          <iyz>-1.9e-05</iyz>
          <izz>0.000404</izz>
        </inertia>
      </inertial>
      <collision name='arm_5_link_collision'>
        <pose frame=''>0 0 0 0 -0 0</pose>
        <geometry>
          <mesh>
            <scale>1 1 1</scale>
            <uri>model://tiago/tiago_description/meshes/arm/arm_5_collision.dae</uri>
          </mesh>
        </geometry>
        <surface>
          <contact>
            <ode/>
          </contact>
          <friction>
            <ode>
              <mu>0.9</mu>
              <mu2>0.9</mu2>
            </ode>
          </friction>
        </surface>
      </collision>
      <visual name='arm_5_link_visual'>
        <pose frame=''>0 0 0 0 -0 0</pose>
        <geometry>
          <mesh>
            <scale>1 1 1</scale>
            <uri>model://tiago/tiago_description/meshes/arm/arm_5.stl</uri>
          </mesh>
        </geometry>
        <material>
          <script>
            <uri>__default__</uri>
            <name>__default__</name>
          </script>
        </material>
      </visual>
      <gravity>0</gravity>
      <velocity_decay/>
    </link>
    <joint name='arm_5_joint' type='revolute'>
      <child>arm_5_link</child>
      <parent>arm_4_link</parent>
      <axis>
        <xyz>0 -1 -0</xyz>
        <limit>
          <lower>-2.0944</lower>
          <upper>2.0944</upper>
          <effort>3</effort>
          <velocity>1.95</velocity>
        </limit>
        <dynamics>
          <damping>1</damping>
          <friction>1</friction>
          <spring_reference>0</spring_reference>
          <spring_stiffness>0</spring_stiffness>
        </dynamics>
        <use_parent_model_frame>1</use_parent_model_frame>
      </axis>
      <physics>
        <ode>
          <implicit_spring_damper>1</implicit_spring_damper>
          <cfm_damping>1</cfm_damping>
          <limit>
            <cfm>0</cfm>
            <erp>0.2</erp>
          </limit>
        </ode>
      </physics>
    </joint>

  <link name='arm_6_link'>
      <pose frame=''>0.086050 -0.73450 0.62000 -0 0 -1.5708</pose>
      <inertial>
        <pose frame=''>0.00531 0.00021 2e-05 0 -0 0</pose>
        <mass>0.28722</mass>
        <inertia>
          <ixx>5.9e-05</ixx>
          <ixy>-0</ixy>
          <ixz>-0</ixz>
          <iyy>0.000106</iyy>
          <iyz>0</iyz>
          <izz>0.000126</izz>
        </inertia>
      </inertial>
      <collision name='arm_6_link_collision'>
        <pose frame=''>0 0 0 0 -0 0</pose>
        <geometry>
          <mesh>
            <scale>1 1 1</scale>
            <uri>model://tiago/tiago_description/meshes/arm/arm_6_collision.dae</uri>
          </mesh>
        </geometry>
        <surface>
          <contact>
            <ode/>
          </contact>
          <friction>
            <ode>
              <mu>0.9</mu>
              <mu2>0.9</mu2>
            </ode>
          </friction>
        </surface>
      </collision>
      <visual name='arm_6_link_visual'>
        <pose frame=''>0 0 0 0 -0 0</pose>
        <geometry>
          <mesh>
            <scale>1 1 1</scale>
            <uri>model://tiago/tiago_description/meshes/arm/arm_6.stl</uri>
          </mesh>
        </geometry>
        <material>
          <script>
            <uri>__default__</uri>
            <name>__default__</name>
          </script>
        </material>
      </visual>
      <gravity>0</gravity>
      <velocity_decay/>
    </link>
    <joint name='arm_6_joint' type='revolute'>
      <child>arm_6_link</child>
      <parent>arm_5_link</parent>
      <axis>
        <xyz>0 -0 1</xyz>
        <limit>
          <lower>-3.0</lower> <!-- Test 21.06.18: Old Value: -1.5708 -->
          <upper>1.5708</upper>
          <effort>6.6</effort>
          <velocity>1.76</velocity>
        </limit>
        <dynamics>
          <damping>1</damping>
          <friction>1</friction>
          <spring_reference>0</spring_reference>
          <spring_stiffness>0</spring_stiffness>
        </dynamics>
        <use_parent_model_frame>1</use_parent_model_frame>
      </axis>
      <physics>
        <ode>
          <implicit_spring_damper>1</implicit_spring_damper>
          <cfm_damping>1</cfm_damping>
          <limit>
            <cfm>0</cfm>
            <erp>0.2</erp>
          </limit>
        </ode>
      </physics>
    </joint>

  <link name='arm_7_link'>
      <pose frame=''>0.086050 -0.73450 0.62000 1.5708 1.5708 0</pose>
      <inertial>
        <pose frame=''>-0.000222 0.00019 0.078363 0 -0 0</pose>
        <mass>0.76211</mass>
        <inertia>
          <ixx>0.00139863</ixx>
          <ixy>4.50179e-05</ixy>
          <ixz>2.23503e-06</ixz>
          <iyy>0.00106617</iyy>
          <iyz>-3.26422e-06</iyz>
          <izz>0.000687486</izz>
        </inertia>
      </inertial>
      <collision name='arm_7_link_fixed_joint_lump__arm_tool_link_collision'>
        <pose frame=''>-0 0 0.047 0 -0 -1.5708</pose>
        <geometry>
          <cylinder>
            <length>0.005</length>
            <radius>0.005</radius>
          </cylinder>
        </geometry>
      </collision>
      <collision name='arm_7_link_fixed_joint_lump__gripper_link_collision_1'>
        <pose frame=''>-0 0 0.056 3.14159 -0 -1.5708</pose>
        <geometry>
          <mesh>
            <scale>1 1 1</scale>
            <uri>model://tiago/pal_gripper_description/meshes/gripper_link_collision.stl</uri>
          </mesh>
        </geometry>
        <surface>
          <contact>
            <ode/>
          </contact>
          <friction>
            <ode/>
          </friction>
        </surface>
      </collision>
      <visual name='arm_7_link_fixed_joint_lump__arm_tool_link_visual'>
        <pose frame=''>-0 0 0.047 0 -0 -1.5708</pose>
        <geometry>
          <cylinder>
            <length>0.005</length>
            <radius>0.005</radius>
          </cylinder>
        </geometry>
      </visual>
      <visual name='arm_7_link_fixed_joint_lump__gripper_link_visual_1'>
        <pose frame=''>-0 0 0.056 3.14159 -0 -1.5708</pose>
        <geometry>
          <mesh>
            <scale>1 1 1</scale>
            <uri>model://tiago/pal_gripper_description/meshes/gripper_link.stl</uri>
          </mesh>
        </geometry>
        <material>
          <script>
            <name>Gazebo/White</name>
            <uri>file://media/materials/scripts/gazebo.material</uri>
          </script>
        </material>
      </visual>
      <velocity_decay/>
      <gravity>0</gravity>
      <velocity_decay/>
    </link>
    <joint name='arm_7_joint' type='revolute'>
      <child>arm_7_link</child>
      <parent>arm_6_link</parent>
      <axis>
        <xyz>0 -1 -0</xyz>
        <limit>
          <lower>-2.8944</lower>
          <upper>2.8000</upper>
          <effort>6.6</effort>
          <velocity>1.76</velocity>
        </limit>
        <dynamics>
          <damping>1</damping>
          <friction>1</friction>
          <spring_reference>0</spring_reference>
          <spring_stiffness>0</spring_stiffness>
        </dynamics>
        <use_parent_model_frame>1</use_parent_model_frame>
      </axis>
      <physics>
        <provide_feedback>1</provide_feedback>
        <ode>
          <provide_feedback>1</provide_feedback>
          <implicit_spring_damper>1</implicit_spring_damper>
          <cfm_damping>1</cfm_damping>
          <limit>
            <cfm>0</cfm>
            <erp>0.2</erp>
          </limit>
        </ode>
      </physics>
    </joint>
    <link name='gripper_left_finger_link'>
	  <pose frame=''>0.037050 -0.78450 0.62 1.57079 3.1416 3.14159</pose>
      <inertial>
        <pose frame=''>-0.00447 0.010766 -0.121013 0 -0 0</pose>
        <mass>0.10998</mass>
        <inertia>
          <ixx>0.000232</ixx>
          <ixy>-5e-06</ixy>
          <ixz>-3.2e-05</ixz>
          <iyy>0.000224</iyy>
          <iyz>3.6e-05</iyz>
          <izz>2.9e-05</izz>
        </inertia>
      </inertial>
      <collision name='gripper_left_finger_link_collision'>
        <pose frame=''>-0.005 0 -0.165 0 -0 3.1415</pose>
        <geometry>
          <box>
            <size>0.01 0.05 0.11</size>
          </box>
        </geometry>
        <surface>
          <contact>
            <ode>
              <kp>1e+06</kp>
              <kd>1</kd>
              <max_vel>1</max_vel>
              <min_depth>0.1</min_depth>
            </ode>
          </contact>
          <friction>
            <ode>
              <mu>1</mu>
              <mu2>1</mu2>
              <fdir1>0 0 0</fdir1>
            </ode>
          </friction>
        </surface>
      </collision>
      <visual name='gripper_left_finger_link_visual'>
        <pose frame=''>0 0 0 0 -0 3.1415</pose>
        <geometry>
          <mesh>
            <scale>1 1 1</scale>
            <uri>model://tiago/pal_gripper_description/meshes/gripper_finger_link.stl</uri>
          </mesh>
        </geometry>
        <material>
          <script>
            <name>Gazebo/Black</name>
            <uri>file://media/materials/scripts/gazebo.material</uri>
          </script>
        </material>
      </visual>
      <velocity_decay/>
      <gravity>0</gravity>
      <velocity_decay/>
    </link>
    <joint name='gripper_left_finger_joint' type='prismatic'>
      <child>gripper_left_finger_link</child>
      <parent>arm_7_link</parent>
      <axis>
        <xyz>1 0 0</xyz>
        <limit>
          <lower>0</lower>
          <upper>0.045</upper>
          <effort>16</effort>
          <velocity>0.05</velocity>
        </limit>
        <dynamics>
          <damping>80</damping>
          <friction>0</friction>
          <spring_reference>0</spring_reference>
          <spring_stiffness>0</spring_stiffness>
        </dynamics>
        <use_parent_model_frame>1</use_parent_model_frame>
      </axis>
      <physics>
        <provide_feedback>1</provide_feedback>
        <ode>
          <provide_feedback>1</provide_feedback>
          <implicit_spring_damper>1</implicit_spring_damper>
          <cfm_damping>1</cfm_damping>
          <limit>
            <cfm>0</cfm>
            <erp>0.2</erp>
          </limit>
        </ode>
      </physics>
    </joint>
    <link name='gripper_right_finger_link'>
      <pose frame=''>0.13505 -0.78450 0.62 1.57079 3.1416 3.14159</pose>
      <inertial>
        <pose frame=''>-0.00447 0.010766 -0.121013 0 -0 0</pose>
        <mass>0.10998</mass>
        <inertia>
          <ixx>0.000232</ixx>
          <ixy>-5e-06</ixy>
          <ixz>-3.2e-05</ixz>
          <iyy>0.000224</iyy>
          <iyz>3.6e-05</iyz>
          <izz>2.9e-05</izz>
        </inertia>
      </inertial>
      <collision name='gripper_right_finger_link_collision'>
        <pose frame=''>0.005 0 -0.165 0 -0 3.1415</pose>
        <geometry>
          <box>
            <size>0.01 0.05 0.11</size>
          </box>
        </geometry>
        <surface>
          <contact>
            <ode>
              <kp>1e+06</kp>
              <kd>1</kd>
              <max_vel>1</max_vel>
              <min_depth>0.1</min_depth>
            </ode>
          </contact>
          <friction>
            <ode>
              <mu>1</mu>
              <mu2>1</mu2>
              <fdir1>0 0 0</fdir1>
            </ode>
          </friction>
        </surface>
      </collision>
      <visual name='gripper_right_finger_link_visual'>
        <pose frame=''>0 0 0 0 -0 3.1415</pose>
        <geometry>
          <mesh>
            <scale>-1 -1 1</scale>
            <uri>model://tiago/pal_gripper_description/meshes/gripper_finger_link.stl</uri>
          </mesh>
        </geometry>
        <material>
          <script>
            <name>Gazebo/Black</name>
            <uri>file://media/materials/scripts/gazebo.material</uri>
          </script>
        </material>
      </visual>
      <velocity_decay/>
      <gravity>0</gravity>
      <velocity_decay/>
    </link>
    <joint name='gripper_right_finger_joint' type='prismatic'>
      <child>gripper_right_finger_link</child>
      <parent>arm_7_link</parent>
      <axis>
        <xyz>-1 0 0</xyz>
        <limit>
          <lower>0</lower>
          <upper>0.045</upper>
          <effort>16</effort>
          <velocity>0.05</velocity>
        </limit>
        <dynamics>
          <damping>80</damping>
          <friction>0</friction>
          <spring_reference>0</spring_reference>
          <spring_stiffness>0</spring_stiffness>
        </dynamics>
        <use_parent_model_frame>1</use_parent_model_frame>
      </axis>
      <physics>
        <provide_feedback>1</provide_feedback>
        <ode>
          <provide_feedback>1</provide_feedback>
          <implicit_spring_damper>1</implicit_spring_damper>
          <cfm_damping>1</cfm_damping>
          <limit>
            <cfm>0</cfm>
            <erp>0.2</erp>
          </limit>
        </ode>
      </physics>
    </joint>

  	<gripper name="Gripper">
    <grasp_check>
        <attach_steps>5</attach_steps>
        <detach_steps>10</detach_steps>
        <min_contact_count>1</min_contact_count>
    </grasp_check>
    <gripper_link>gripper_left_finger_link</gripper_link>
    <palm_link>gripper_right_finger_link</palm_link>
  	</gripper>

    <static>0</static>
  </model>
</sdf>
