#VRML_SIM R2022b utf8
# tags: hidden
PROTO Mir250CasterWheel [
  field SFVec3f    translation           0 0 0
  field SFRotation rotation              0 0 1 0
  field SFString   name                  ""
]
{
Transform {
  translation IS translation
  rotation IS rotation
  children [
    HingeJoint {
      jointParameters HingeJointParameters {
        axis 0 0 1
        dampingConstant 0.01
      }
      endPoint Solid {
        name IS name
        children [
          DEF CASTER_CYL Shape {
            appearance DEF BLACK PBRAppearance {
              baseColor 0 0 0
              roughness 1
              metalness 0
            }
            geometry Cylinder {
              height 0.02
              radius 0.025
            }
          }
          Transform {
            translation -0.021 0.02 -0.035
            rotation 0 1 0 0.54035
            children [
              DEF CASTER_RAILING Shape {
                appearance USE BLACK
                geometry Box {
                  size 0.03 0.0075 0.1
                }
              }
            ]
          }
          Transform {
            translation -0.021 -0.02 -0.035
            rotation 0 1 0 0.54035
            children [
              USE CASTER_RAILING
            ]
          }
          HingeJoint {
            jointParameters HingeJointParameters {
              axis 0 1 0
              anchor -0.042 0 -0.07
            }
            endPoint Solid {
              translation -0.042 0 -0.07
              rotation 1 0 0 -1.5708
              children [
                Group {
                  children [
                    Shape {
                      appearance USE BLACK
                      geometry Cylinder {
                        height 0.032
                        radius 0.045
                      }
                    }
                    Shape {
                      appearance PBRAppearance {
                        baseColor 0.53 0.54 0.52
                        roughness 1
                        metalness 0
                      }
                      geometry Cylinder {
                        height 0.03
                        radius 0.06
                      }
                    }
                  ]
                }
              ]
              contactMaterial "Mir250Wheel"
              boundingObject Cylinder {
                height 0.005
                radius 0.06
              }
              physics Physics {
                density -1
                mass 1
              }
            }
          }
        ]
        boundingObject USE CASTER_CYL
        physics Physics {
          density -1
          mass 0.3
        }
      }
    }
  ]
}
}

