#VRML_SIM R2022a utf8
# license: Apache License 2.0
# license url: http://www.apache.org/licenses/LICENSE-2.0
# Roboto arm UR5 from Universal Robots with 6 degrees of freedom.

# how UR5.proto was made from UR5.urdf (linux commands):

# mkdir /tmp/UR5
# cd /tmp/UR5
# git clone https://github.com/cyberbotics/urdf2webots
# (maybe cd urdf2webots, pip install -r requirements.txt, cd /tmp/UR5)
# git clone https://github.com/ros-industrial/robot_movement_interface
# cd robot_movement_interface/dependencies/ur_description/urdf/
# python3 /tmp/UR5/urdf2webots/demo.py --input=ur5_robot.urdf --output=UR5.proto --link-to-def --joint-to-def --static-base --tool-slot=ee_link
# wget https://raw.githubusercontent.com/cyberbotics/webots/master/scripts/proto_splitter/proto2multi.py
# wget https://raw.githubusercontent.com/cyberbotics/webots/master/scripts/proto_splitter/proto2mesh.py
# python3 proto2multi.py --input=$(readlink -f UR5.proto)
# python3 proto2mesh.py $(readlink -f UR5.proto)

# copy UR5_multifile/UR5.proto and UR5_multifile/UR5 to your proto folder

# remove trailing zeroes in numbers, fix toolSlot,
# replace geometry by boundingObject where needed

PROTO UR5 [
  field  SFVec3f     translation     0 0 0
  field  SFRotation  rotation        1 0 0 0
  field  SFString    name            "UR5"  # Is `Robot.name`.
  field  SFString    controller      "void" # Is `Robot.controller`.
  field  MFString    controllerArgs  []     # Is `Robot.controllerArgs`.
  field  SFString    customData      ""     # Is `Robot.customData`.
  field  SFBool      supervisor      FALSE  # Is `Robot.supervisor`.
  field  SFBool      synchronization TRUE   # Is `Robot.synchronization`.
  field  SFBool      selfCollision   FALSE  # Is `Robot.selfCollision`.
  field  SFBool      staticBase      TRUE   # Defines if the robot base should be pinned to the static environment.
  field  MFNode      toolSlot        []     # Extend the robot with new nodes at the end of the arm.
]
{
  Robot {
    translation IS translation
    rotation IS rotation
    controller IS controller
    controllerArgs IS controllerArgs
    customData IS customData
    supervisor IS supervisor
    synchronization IS synchronization
    selfCollision IS selfCollision
    children [
      Shape {
        appearance PBRAppearance {
          baseColor 0.524800 0.524800 0.524800
          transparency 0
          roughness 0.375000
          metalness 0
          emissiveColor 0 0 0
        }
        geometry DEF Base_0 Mesh {
          url "UR5/base_0.obj"
        }
      }
      Shape {
        appearance PBRAppearance {
          baseColor 0.064000 0.064000 0.064000
          transparency 0
          roughness 0.375000
          metalness 0
          emissiveColor 0 0 0
        }
        geometry DEF Base_1 Mesh {
          url "UR5/base_1.obj"
        }
      }
      DEF shoulder_pan_joint HingeJoint {
        jointParameters HingeJointParameters {
          axis 0 0 1
          anchor 0 0 0.089159
          dampingConstant 0.0
          staticFriction 0.0
        }
        device [
          RotationalMotor {
            name "shoulder_pan_joint"
            maxVelocity 3.15
            minPosition -6.2831853
            maxPosition 6.2831853
            maxTorque 150.0
          }
          PositionSensor {
            name "shoulder_pan_joint_sensor"
          }
        ]
        endPoint DEF shoulder_link Solid {
          translation 0 0 0.089159
          rotation 0 1 0 0
          children [
            Shape {
              appearance PBRAppearance {
                baseColor 0.178400 0.178400 0.178400
                transparency 0
                roughness 0.375000
                metalness 0
                emissiveColor 0 0 0
              }
              geometry DEF Shoulder_0 Mesh {
                url "UR5/shoulder_0.obj"
              }
            }
            Shape {
              appearance PBRAppearance {
                baseColor 0.064000 0.064000 0.064000
                transparency 0
                roughness 0.375000
                metalness 0
                emissiveColor 0 0 0
              }
              geometry DEF Shoulder_1 Mesh {
                url "UR5/shoulder_1.obj"
              }
            }
            Shape {
              appearance PBRAppearance {
                baseColor 0.313600 0.434400 0.512000
                transparency 0
                roughness 0.375000
                metalness 0
                emissiveColor 0 0 0
              }
              geometry DEF Shoulder_2 Mesh {
                url "UR5/shoulder_2.obj"
              }
            }
            DEF shoulder_lift_joint HingeJoint {
              jointParameters HingeJointParameters {
                axis 0 1 0
                anchor 0 0.135850 0
                dampingConstant 0.0
                staticFriction 0.0
              }
              device [
                RotationalMotor {
                  name "shoulder_lift_joint"
                  maxVelocity 3.15
                  minPosition -6.2831853
                  maxPosition 6.2831853
                  maxTorque 150.0
                }
                PositionSensor {
                  name "shoulder_lift_joint_sensor"
                }
              ]
              endPoint DEF upper_arm_link Solid {
                translation 0 0.135850 0
                rotation 0 1 0 1.570796
                children [
                  Shape {
                    appearance PBRAppearance {
                      baseColor 0.142720 0.142720 0.142720
                      transparency 0
                      roughness 0.437500
                      metalness 0
                      emissiveColor 0 0 0
                    }
                    geometry DEF UpperArm_0 Mesh {
                      url "UR5/upperarm_0.obj"
                    }
                  }
                  Shape {
                    appearance PBRAppearance {
                      baseColor 0.051200 0.051200 0.051200
                      transparency 0
                      roughness 0.437500
                      metalness 0
                      emissiveColor 0 0 0
                    }
                    geometry DEF UpperArm_1 Mesh {
                      url "UR5/upperarm_1.obj"
                    }
                  }
                  Shape {
                    appearance PBRAppearance {
                      baseColor 0.250880 0.347520 0.409600
                      transparency 0
                      roughness 0.437500
                      metalness 0
                      emissiveColor 0 0 0
                    }
                    geometry DEF UpperArm_2 Mesh {
                      url "UR5/upperarm_2.obj"
                    }
                  }
                  Shape {
                    appearance PBRAppearance {
                      baseColor 0.142720 0.142720 0.142720
                      transparency 0
                      roughness 0.437500
                      metalness 0
                      emissiveColor 0 0 0
                    }
                    geometry DEF UpperArm_3 Mesh {
                      url "UR5/upperarm_3.obj"
                    }
                  }
                  Shape {
                    appearance PBRAppearance {
                      baseColor 0.051200 0.051200 0.051200
                      transparency 0
                      roughness 0.437500
                      metalness 0
                      emissiveColor 0 0 0
                    }
                    geometry DEF UpperArm_4 Mesh {
                      url "UR5/upperarm_4.obj"
                    }
                  }
                  Shape {
                    appearance PBRAppearance {
                      baseColor 0.419840 0.419840 0.419840
                      transparency 0
                      roughness 0.437500
                      metalness 0
                      emissiveColor 0 0 0
                    }
                    geometry DEF UpperArm_5 Mesh {
                      url "UR5/upperarm_5.obj"
                    }
                  }
                  Shape {
                    appearance PBRAppearance {
                      baseColor 0.250880 0.347520 0.409600
                      transparency 0
                      roughness 0.437500
                      metalness 0
                      emissiveColor 0 0 0
                    }
                    geometry DEF UpperArm_6 Mesh {
                      url "UR5/upperarm_6.obj"
                    }
                  }
                  DEF elbow_joint HingeJoint {
                    jointParameters HingeJointParameters {
                      axis 0 1 0
                      anchor 0 -0.119700 0.425000
                      dampingConstant 0.0
                      staticFriction 0.0
                    }
                    device [
                      RotationalMotor {
                        name "elbow_joint"
                        maxVelocity 3.15
                        minPosition -6.2831853
                        maxPosition 6.2831853
                        maxTorque 150.0
                      }
                      PositionSensor {
                        name "elbow_joint_sensor"
                      }
                    ]
                    endPoint DEF forearm_link Solid {
                      translation 0 -0.119700 0.425000
                      rotation 0 1 0 0
                      children [
                        Shape {
                          appearance PBRAppearance {
                            baseColor 0.250880 0.347520 0.409600
                            transparency 0
                            roughness 0.437500
                            metalness 0
                            emissiveColor 0 0 0
                          }
                          geometry DEF Forearm_0 Mesh {
                            url "UR5/forearm_0.obj"
                          }
                        }
                        Shape {
                          appearance PBRAppearance {
                            baseColor 0.419840 0.419840 0.419840
                            transparency 0
                            roughness 0.437500
                            metalness 0
                            emissiveColor 0 0 0
                          }
                          geometry DEF Forearm_1 Mesh {
                            url "UR5/forearm_1.obj"
                          }
                        }
                        Shape {
                          appearance PBRAppearance {
                            baseColor 0.142720 0.142720 0.142720
                            transparency 0
                            roughness 0.437500
                            metalness 0
                            emissiveColor 0 0 0
                          }
                          geometry DEF Forearm_2 Mesh {
                            url "UR5/forearm_2.obj"
                          }
                        }
                        Shape {
                          appearance PBRAppearance {
                            baseColor 0.142720 0.142720 0.142720
                            transparency 0
                            roughness 0.437500
                            metalness 0
                            emissiveColor 0 0 0
                          }
                          geometry DEF Forearm_3 Mesh {
                            url "UR5/forearm_3.obj"
                          }
                        }
                        DEF wrist_1_joint HingeJoint {
                          jointParameters HingeJointParameters {
                            axis 0 1 0
                            anchor 0 0 0.392250
                            dampingConstant 0.0
                            staticFriction 0.0
                          }
                          device [
                            RotationalMotor {
                              name "wrist_1_joint"
                              maxVelocity 3.2
                              minPosition -6.2831853
                              maxPosition 6.2831853
                              maxTorque 28.0
                            }
                            PositionSensor {
                              name "wrist_1_joint_sensor"
                            }
                          ]
                          endPoint DEF wrist_1_link Solid {
                            translation 0 0 0.392250
                            rotation 0 1 0 1.570796
                            children [
                              Shape {
                                appearance PBRAppearance {
                                  baseColor 0.051200 0.051200 0.051200
                                  transparency 0
                                  roughness 0.437500
                                  metalness 0
                                  emissiveColor 0 0 0
                                }
                                geometry DEF Wrist1_0 Mesh {
                                  url "UR5/wrist1_0.obj"
                                }
                              }
                              Shape {
                                appearance PBRAppearance {
                                  baseColor 0.142720 0.142720 0.142720
                                  transparency 0
                                  roughness 0.437500
                                  metalness 0
                                  emissiveColor 0 0 0
                                }
                                geometry DEF Wrist1_1 Mesh {
                                  url "UR5/wrist1_1.obj"
                                }
                              }
                              Shape {
                                appearance PBRAppearance {
                                  baseColor 0.250880 0.347520 0.409600
                                  transparency 0
                                  roughness 0.437500
                                  metalness 0
                                  emissiveColor 0 0 0
                                }
                                geometry DEF Wrist1_2 Mesh {
                                  url "UR5/wrist1_2.obj"
                                }
                              }
                              DEF wrist_2_joint HingeJoint {
                                jointParameters HingeJointParameters {
                                  axis 0 0 1
                                  anchor 0 0.093000 0
                                  dampingConstant 0.0
                                  staticFriction 0.0
                                }
                                device [
                                  RotationalMotor {
                                    name "wrist_2_joint"
                                    maxVelocity 3.2
                                    minPosition -6.2831853
                                    maxPosition 6.2831853
                                    maxTorque 28.0
                                  }
                                  PositionSensor {
                                    name "wrist_2_joint_sensor"
                                  }
                                ]
                                endPoint DEF wrist_2_link Solid {
                                  translation 0 0.093000 0
                                  rotation 0 1 0 0
                                  children [
                                    Shape {
                                      appearance PBRAppearance {
                                        baseColor 0.051200 0.051200 0.051200
                                        transparency 0
                                        roughness 0.437500
                                        metalness 0
                                        emissiveColor 0 0 0
                                      }
                                      geometry DEF Wrist2_0 Mesh {
                                        url "UR5/wrist2_0.obj"
                                      }
                                    }
                                    Shape {
                                      appearance PBRAppearance {
                                        baseColor 0.142720 0.142720 0.142720
                                        transparency 0
                                        roughness 0.437500
                                        metalness 0
                                        emissiveColor 0 0 0
                                      }
                                      geometry DEF Wrist2_1 Mesh {
                                        url "UR5/wrist2_1.obj"
                                      }
                                    }
                                    Shape {
                                      appearance PBRAppearance {
                                        baseColor 0.250880 0.347520 0.409600
                                        transparency 0
                                        roughness 0.437500
                                        metalness 0
                                        emissiveColor 0 0 0
                                      }
                                      geometry DEF Wrist2_2 Mesh {
                                        url "UR5/wrist2_2.obj"
                                      }
                                    }
                                    DEF wrist_3_joint HingeJoint {
                                      jointParameters HingeJointParameters {
                                        axis 0 1 0
                                        anchor 0 0 0.094650
                                        dampingConstant 0.0
                                        staticFriction 0.0
                                      }
                                      device [
                                        RotationalMotor {
                                          name "wrist_3_joint"
                                          maxVelocity 3.2
                                          minPosition -6.2831853
                                          maxPosition 6.2831853
                                          maxTorque 28.0
                                        }
                                        PositionSensor {
                                          name "wrist_3_joint_sensor"
                                        }
                                      ]
                                      endPoint DEF wrist_3_link Solid {
                                        translation 0 0 0.094650
                                        rotation 0 1 0 0
                                        children [
                                          Shape {
                                            appearance PBRAppearance {
                                              baseColor 0.214958 0.214958 0.214958
                                              transparency 0
                                              roughness 0.492188
                                              metalness 0
                                              emissiveColor 0 0 0
                                            }
                                            geometry DEF Wrist3_0 Mesh {
                                              url "UR5/wrist3_0.obj"
                                            }
                                          }
                                          Shape {
                                            appearance PBRAppearance {
                                              baseColor 0.099589 0.103444 0.108584
                                              transparency 0
                                              roughness 0.990094
                                              metalness 0
                                              emissiveColor 0 0 0
                                            }
                                            geometry DEF Wrist3_1 Mesh {
                                              url "UR5/wrist3_1.obj"
                                            }
                                          }
                                          DEF toolSlot Transform {
                                            translation 0 0.0823 0
                                            children IS toolSlot
                                          }
                                        ]
                                        name "wrist_3_link"
                                        boundingObject DEF wrist_3 Mesh {
                                          url "UR5/wrist_3.obj"
                                        }
                                        physics Physics {
                                          density -1
                                          mass 0.187900
                                          centerOfMass [ 0 0 0 ]
                                          inertiaMatrix [
                                            1.713647e-02 1.713647e-02 3.382200e-02
                                            0.000000e+00 0.000000e+00 0.000000e+00
                                          ]
                                        }
                                      }
                                    }
                                  ]
                                  name "wrist_2_link"
                                  boundingObject DEF wrist_2 Mesh {
                                    url "UR5/wrist_2.obj"
                                  }
                                  physics Physics {
                                    density -1
                                    mass 1.219000
                                    centerOfMass [ 0 0 0 ]
                                    inertiaMatrix [
                                      1.111728e-01 1.111728e-01 2.194200e-01
                                      0.000000e+00 0.000000e+00 0.000000e+00
                                    ]
                                  }
                                }
                              }
                            ]
                            name "wrist_1_link"
                            boundingObject DEF wrist_1 Mesh {
                              url "UR5/wrist_1.obj"
                            }
                            physics Physics {
                              density -1
                              mass 1.219000
                              centerOfMass [ 0 0 0 ]
                              inertiaMatrix [
                                1.111728e-01 1.111728e-01 2.194200e-01
                                0.000000e+00 0.000000e+00 0.000000e+00
                              ]
                            }
                          }
                        }
                      ]
                      name "forearm_link"
                      boundingObject DEF forearm Mesh {
                        url "UR5/forearm.obj"
                      }
                      physics Physics {
                        density -1
                        mass 2.275000
                        centerOfMass [ 0 0 0.250000 ]
                        inertiaMatrix [
                          4.944331e-02 4.944331e-02 4.095000e-03
                          0.000000e+00 0.000000e+00 0.000000e+00
                        ]
                      }
                    }
                  }
                ]
                name "upper_arm_link"
                boundingObject DEF upper_arm Mesh {
                  url "UR5/upper_arm.obj"
                }
                physics Physics {
                  density -1
                  mass 8.393000
                  centerOfMass [ 0 0 0.280000 ]
                  inertiaMatrix [
                    2.268907e-01 2.268907e-01 1.510740e-02
                    0.000000e+00 0.000000e+00 0.000000e+00
                  ]
                }
              }
            }
          ]
          name "shoulder_link"
          boundingObject DEF shoulder Mesh {
            url "UR5/shoulder.obj"
          }
          physics Physics {
            density -1
            mass 3.700000
            centerOfMass [ 0 0 0 ]
            inertiaMatrix [
              1.026750e-02 1.026750e-02 6.660000e-03
              0.000000e+00 0.000000e+00 0.000000e+00
            ]
          }
        }
      }
    ]
    name IS name 
    model "UR5"
    boundingObject DEF base Mesh {
      url "UR5/base.obj"
    }
    %{ if fields.staticBase.value == false then }%
    physics Physics {
      density -1
      mass 4.000000
      centerOfMass [ 0 0 0 ]
      inertiaMatrix [
        4.433332e-03 4.433332e-03 7.200000e-03
        0.000000e+00 0.000000e+00 0.000000e+00
      ]
    }
    %{ end }%
  }
}
