<sdf version='1.4'>
  <model name='robot'>
    <link name='base_footprint'>
      <pose>0 0 0 0 -0 0</pose>
      <inertial>
        <pose>-0.00983617 -0.0015008 0.21148 0 -0 0</pose>
        <mass>43.4016</mass>
        <inertia>
          <ixx>2.04327</ixx>
          <ixy>0.000744547</ixy>
          <ixz>0.109545</ixz>
          <iyy>2.13173</iyy>
          <iyz>0.0140814</iyz>
          <izz>0.688729</izz>
        </inertia>
      </inertial>
      <collision name='base_footprint_collision_base_antenna_left_link'>
        <pose>-0.201 0.1062 0.3785 0 -0 0</pose>
        <geometry>
          <cylinder>
            <length>0.17</length>
            <radius>0.005</radius>
          </cylinder>
        </geometry>
        <laser_retro>0</laser_retro>
        <surface>
          <contact>
            <ode>
              <kp>1e+08</kp>
              <kd>10</kd>
              <max_vel>10</max_vel>
              <min_depth>0.0005</min_depth>
            </ode>
          </contact>
          <friction>
            <ode>
              <mu>0.1</mu>
              <mu2>0.1</mu2>
              <fdir1>1 0 0</fdir1>
            </ode>
          </friction>
        </surface>
        <surface>
          <contact>
            <ode/>
          </contact>
          <friction>
            <ode/>
          </friction>
        </surface>
      </collision>
      <collision name='base_footprint_collision_base_antenna_right_link'>
        <pose>-0.201 -0.1062 0.3785 0 -0 0</pose>
        <geometry>
          <cylinder>
            <length>0.17</length>
            <radius>0.005</radius>
          </cylinder>
        </geometry>
        <laser_retro>0</laser_retro>
        <surface>
          <contact>
            <ode>
              <kp>1e+08</kp>
              <kd>10</kd>
              <max_vel>10</max_vel>
              <min_depth>0.0005</min_depth>
            </ode>
          </contact>
          <friction>
            <ode>
              <mu>0.1</mu>
              <mu2>0.1</mu2>
              <fdir1>1 0 0</fdir1>
            </ode>
          </friction>
        </surface>
        <surface>
          <contact>
            <ode/>
          </contact>
          <friction>
            <ode/>
          </friction>
        </surface>
      </collision>
      <collision name='base_footprint_collision_base_link'>
        <pose>0 0 0.0985 0 -0 0</pose>
        <geometry>
          <mesh>
            <scale>1 1 1</scale>
            <uri>models/tiago/pmb2_description/meshes/base/base_collision.dae</uri>
          </mesh>
        </geometry>
        <laser_retro>0</laser_retro>
        <surface>
          <contact>
            <ode>
              <kp>1e+08</kp>
              <kd>10</kd>
              <max_vel>10</max_vel>
              <min_depth>0.0005</min_depth>
            </ode>
          </contact>
          <friction>
            <ode>
              <mu>0.1</mu>
              <mu2>0.1</mu2>
              <fdir1>1 0 0</fdir1>
            </ode>
          </friction>
        </surface>
        <surface>
          <contact>
            <ode/>
          </contact>
          <friction>
            <ode/>
          </friction>
        </surface>
      </collision>
      <collision name='base_footprint_collision_torso_fixed_column_link'>
        <pose>-0.062 0 0.5685 0 -0 0</pose>
        <geometry>
          <box>
            <size>0.23 0.23 0.55</size>
          </box>
        </geometry>
        <laser_retro>0</laser_retro>
        <surface>
          <contact>
            <ode>
              <kp>1e+08</kp>
              <kd>10</kd>
              <max_vel>10</max_vel>
              <min_depth>0.0005</min_depth>
            </ode>
          </contact>
          <friction>
            <ode>
              <mu>0.1</mu>
              <mu2>0.1</mu2>
              <fdir1>1 0 0</fdir1>
            </ode>
          </friction>
        </surface>
        <surface>
          <contact>
            <ode/>
          </contact>
          <friction>
            <ode/>
          </friction>
        </surface>
      </collision>
      <collision name='base_footprint_collision_torso_fixed_link'>
        <pose>0.023 0 0.3115 0 -0 0</pose>
        <geometry>
          <box>
            <size>0.4 0.25 0.04</size>
          </box>
        </geometry>
        <laser_retro>0</laser_retro>
        <surface>
          <contact>
            <ode>
              <kp>1e+08</kp>
              <kd>10</kd>
              <max_vel>10</max_vel>
              <min_depth>0.0005</min_depth>
            </ode>
          </contact>
          <friction>
            <ode>
              <mu>0.1</mu>
              <mu2>0.1</mu2>
              <fdir1>1 0 0</fdir1>
            </ode>
          </friction>
        </surface>
      </collision>
      <collision name='base_footprint_collision_torso_fixed_link_1'>
        <pose>-0.062 0 0.3415 0 -0 0</pose>
        <geometry>
          <box>
            <size>0.25 0.25 0.1</size>
          </box>
        </geometry>
        <laser_retro>0</laser_retro>
        <surface>
          <contact>
            <ode>
              <kp>1e+08</kp>
              <kd>10</kd>
              <max_vel>10</max_vel>
              <min_depth>0.0005</min_depth>
            </ode>
          </contact>
          <friction>
            <ode>
              <mu>0.1</mu>
              <mu2>0.1</mu2>
              <fdir1>1 0 0</fdir1>
            </ode>
          </friction>
        </surface>
      </collision>
      <visual name='base_footprint_visual_base_antenna_left_link'>
        <pose>-0.201 0.1062 0.2935 0 -0 0</pose>
        <geometry>
          <mesh>
            <scale>1 1 1</scale>
            <uri>models/tiago/pmb2_description/meshes/objects/antenna.stl</uri>
          </mesh>
        </geometry>
        <material>
          <script>
            <name>Gazebo/Black</name>
            <uri>__default__</uri>
          </script>
        </material>
      </visual>
      <visual name='base_footprint_visual_base_antenna_right_link'>
        <pose>-0.201 -0.1062 0.2935 0 -0 0</pose>
        <geometry>
          <mesh>
            <scale>1 1 1</scale>
            <uri>models/tiago/pmb2_description/meshes/objects/antenna.stl</uri>
          </mesh>
        </geometry>
        <material>
          <script>
            <name>Gazebo/Black</name>
            <uri>__default__</uri>
          </script>
        </material>
      </visual>
      <visual name='base_footprint_visual_base_cover_link'>
        <pose>0 0 0.13 0 -0 0</pose>
        <geometry>
          <mesh>
            <scale>1 1 1</scale>
            <uri>models/tiago/pmb2_description/meshes/base/base_ring.stl</uri>
          </mesh>
        </geometry>
        <material>
          <script>
            <name>Gazebo/Orange</name>
            <uri>__default__</uri>
          </script>
        </material>
      </visual>
      <visual name='base_footprint_visual_base_laser_link'>
        <pose>0.202 0 0.0945 0 -0 0</pose>
        <geometry>
          <mesh>
            <scale>1 1 1</scale>
            <uri>models/tiago/pmb2_description/meshes/sensors/sick_tim551.stl</uri>
          </mesh>
        </geometry>
        <material>
          <script>
            <name>Gazebo/DarkGrey</name>
            <uri>__default__</uri>
          </script>
        </material>
      </visual>
      <visual name='base_footprint_visual_base_link'>
        <pose>0 0 0.0985 0 -0 0</pose>
        <geometry>
          <mesh>
            <scale>1 1 1</scale>
            <uri>models/tiago/pmb2_description/meshes/base/base.stl</uri>
          </mesh>
        </geometry>
        <material>
          <script>
            <name>Gazebo/White</name>
            <uri>__default__</uri>
          </script>
        </material>
      </visual>
      <visual name='base_footprint_visual_base_sonar_01_link'>
        <pose>-0.183 -0.183 0.2715 0 -0 -2.35619</pose>
        <geometry>
          <mesh>
            <scale>1 1 1</scale>
            <uri>models/tiago/pmb2_description/meshes/sensors/srf05.stl</uri>
          </mesh>
        </geometry>
        <material>
          <script>
            <name>Gazebo/DarkGrey</name>
            <uri>__default__</uri>
          </script>
        </material>
      </visual>
      <visual name='base_footprint_visual_base_sonar_02_link'>
        <pose>-0.259 0 0.2715 0 -0 -3.14159</pose>
        <geometry>
          <mesh>
            <scale>1 1 1</scale>
            <uri>models/tiago/pmb2_description/meshes/sensors/srf05.stl</uri>
          </mesh>
        </geometry>
        <material>
          <script>
            <name>Gazebo/DarkGrey</name>
            <uri>__default__</uri>
          </script>
        </material>
      </visual>
      <visual name='base_footprint_visual_base_sonar_03_link'>
        <pose>-0.183 0.183 0.2715 0 -0 2.35619</pose>
        <geometry>
          <mesh>
            <scale>1 1 1</scale>
            <uri>models/tiago/pmb2_description/meshes/sensors/srf05.stl</uri>
          </mesh>
        </geometry>
        <material>
          <script>
            <name>Gazebo/DarkGrey</name>
            <uri>__default__</uri>
          </script>
        </material>
      </visual>
      <visual name='base_footprint_visual_caster_back_left_1_link'>
        <pose>-0.1735 0.102 0.065 0 -0 0</pose>
        <geometry>
          <mesh>
            <scale>1 1 1</scale>
            <uri>models/tiago/pmb2_description/meshes/wheels/caster_1.stl</uri>
          </mesh>
        </geometry>
      </visual>
      <visual name='base_footprint_visual_caster_back_left_2_link'>
        <pose>-0.1895 0.102 0.025 -1.5708 0 0</pose>
        <geometry>
          <mesh>
            <scale>1 1 1</scale>
            <uri>models/tiago/pmb2_description/meshes/wheels/caster_2.stl</uri>
          </mesh>
        </geometry>
      </visual>
      <visual name='base_footprint_visual_caster_back_right_1_link'>
        <pose>-0.1735 -0.102 0.065 0 -0 0</pose>
        <geometry>
          <mesh>
            <scale>1 1 1</scale>
            <uri>models/tiago/pmb2_description/meshes/wheels/caster_1.stl</uri>
          </mesh>
        </geometry>
      </visual>
      <visual name='base_footprint_visual_caster_back_right_2_link'>
        <pose>-0.1895 -0.102 0.025 -1.5708 0 0</pose>
        <geometry>
          <mesh>
            <scale>1 1 1</scale>
            <uri>models/tiago/pmb2_description/meshes/wheels/caster_2.stl</uri>
          </mesh>
        </geometry>
      </visual>
      <visual name='base_footprint_visual_caster_front_left_1_link'>
        <pose>0.1695 0.102 0.065 0 -0 0</pose>
        <geometry>
          <mesh>
            <scale>1 1 1</scale>
            <uri>models/tiago/pmb2_description/meshes/wheels/caster_1.stl</uri>
          </mesh>
        </geometry>
      </visual>
      <visual name='base_footprint_visual_caster_front_left_2_link'>
        <pose>0.1535 0.102 0.025 -1.5708 0 0</pose>
        <geometry>
          <mesh>
            <scale>1 1 1</scale>
            <uri>models/tiago/pmb2_description/meshes/wheels/caster_2.stl</uri>
          </mesh>
        </geometry>
      </visual>
      <visual name='base_footprint_visual_caster_front_right_1_link'>
        <pose>0.1695 -0.102 0.065 0 -0 0</pose>
        <geometry>
          <mesh>
            <scale>1 1 1</scale>
            <uri>models/tiago/pmb2_description/meshes/wheels/caster_1.stl</uri>
          </mesh>
        </geometry>
      </visual>
      <visual name='base_footprint_visual_caster_front_right_2_link'>
        <pose>0.1535 -0.102 0.025 -1.5708 0 0</pose>
        <geometry>
          <mesh>
            <scale>1 1 1</scale>
            <uri>models/tiago/pmb2_description/meshes/wheels/caster_2.stl</uri>
          </mesh>
        </geometry>
      </visual>
      <visual name='base_footprint_visual_torso_fixed_column_link'>
        <pose>-0.062 0 0.5685 0 -0 0</pose>
        <geometry>
          <box>
            <size>0.18 0.2 0.55</size>
          </box>
        </geometry>
        <material>
          <script>
            <name>Gazebo/DarkGrey</name>
            <uri>__default__</uri>
          </script>
        </material>
      </visual>
      <visual name='base_footprint_visual_torso_fixed_link'>
        <pose>-0.062 0 0.2915 0 -0 0</pose>
        <geometry>
          <mesh>
            <scale>1 1 1</scale>
            <uri>models/tiago/tiago_description/meshes/torso/torso_fix.stl</uri>
          </mesh>
        </geometry>
      </visual>
      <velocity_decay>
        <linear>0</linear>
        <angular>0</angular>
      </velocity_decay>
      <velocity_decay>
        <linear>0</linear>
        <angular>0</angular>
      </velocity_decay>
      <velocity_decay>
        <linear>0</linear>
        <angular>0</angular>
      </velocity_decay>
      <velocity_decay>
        <linear>0</linear>
        <angular>0</angular>
      </velocity_decay>
      <velocity_decay>
        <linear>0</linear>
        <angular>0</angular>
      </velocity_decay>
      <sensor name='imu_sensor' type='imu'>
        <always_on>1</always_on>
        <update_rate>1000</update_rate>
        <imu>
          <noise>
            <type>gaussian</type>
            <rate>
              <mean>0</mean>
              <stddev>0.0002</stddev>
              <bias_mean>7.5e-06</bias_mean>
              <bias_stddev>8e-07</bias_stddev>
            </rate>
            <accel>
              <mean>0</mean>
              <stddev>0.017</stddev>
              <bias_mean>0.1</bias_mean>
              <bias_stddev>0.001</bias_stddev>
            </accel>
          </noise>
        </imu>
        <pose>0.10171 0 0.21132 0 0 -1.5708</pose>
      </sensor>
      <velocity_decay>
        <linear>0</linear>
        <angular>0</angular>
      </velocity_decay>
      <sensor name='base_imu_sensor' type='imu'>
        <always_on>1</always_on>
        <update_rate>100</update_rate>
        <imu>
          <noise>
            <type>gaussian</type>
            <rate>
              <mean>0</mean>
              <stddev>0.0002</stddev>
              <bias_mean>7.5e-06</bias_mean>
              <bias_stddev>8e-07</bias_stddev>
            </rate>
            <accel>
              <mean>0</mean>
              <stddev>0.017</stddev>
              <bias_mean>0.1</bias_mean>
              <bias_stddev>0.001</bias_stddev>
            </accel>
          </noise>
        </imu>
        <pose>0.10171 0 0.21132 0 0 -1.5708</pose>
      </sensor>
      <velocity_decay>
        <linear>0</linear>
        <angular>0</angular>
      </velocity_decay>
      <sensor name='base_laser' type='ray'>
        <update_rate>10</update_rate>
        <visualize>1</visualize>
        <ray>
          <scan>
            <horizontal>
              <samples>640</samples>
              <resolution>1</resolution>
              <min_angle>-1.91986</min_angle>
              <max_angle>1.91986</max_angle>
            </horizontal>
          </scan>
          <range>
            <min>0.05</min>
            <max>10</max>
            <resolution>0.001</resolution>
          </range>
        </ray>
        <pose>0.202 0 0.0945 0 -0 0</pose>
      	<!-- Attach the plugin to this model -->
		<!--      	
		<plugin name="laserScanPlugin" filename="liblaserScanPlugin.so">
      	</plugin>
		-->
	  </sensor>
      <velocity_decay>
        <linear>0</linear>
        <angular>0</angular>
      </velocity_decay>
      <sensor name='base_sonar_01' type='ray'>
        <update_rate>5</update_rate>
        <visualize>0</visualize>
        <ray>
          <scan>
            <horizontal>
              <samples>5</samples>
              <resolution>1</resolution>
              <min_angle>-0.25</min_angle>
              <max_angle>0.25</max_angle>
            </horizontal>
            <vertical>
              <samples>5</samples>
              <resolution>1</resolution>
              <min_angle>-0.25</min_angle>
              <max_angle>0.25</max_angle>
            </vertical>
          </scan>
          <range>
            <min>0.02</min>
            <max>2</max>
            <resolution>0.01</resolution>
          </range>
        </ray>
        <pose>-0.183 -0.183 0.2715 0 -0 -2.35619</pose>
      </sensor>
      <velocity_decay>
        <linear>0</linear>
        <angular>0</angular>
      </velocity_decay>
      <sensor name='base_sonar_02' type='ray'>
        <update_rate>5</update_rate>
        <visualize>0</visualize>
        <ray>
          <scan>
            <horizontal>
              <samples>5</samples>
              <resolution>1</resolution>
              <min_angle>-0.25</min_angle>
              <max_angle>0.25</max_angle>
            </horizontal>
            <vertical>
              <samples>5</samples>
              <resolution>1</resolution>
              <min_angle>-0.25</min_angle>
              <max_angle>0.25</max_angle>
            </vertical>
          </scan>
          <range>
            <min>0.02</min>
            <max>2</max>
            <resolution>0.01</resolution>
          </range>
        </ray>
        <pose>-0.259 0 0.2715 0 -0 -3.14159</pose>
      </sensor>
      <velocity_decay>
        <linear>0</linear>
        <angular>0</angular>
      </velocity_decay>
      <sensor name='base_sonar_03' type='ray'>
        <update_rate>5</update_rate>
        <visualize>0</visualize>
        <ray>
          <scan>
            <horizontal>
              <samples>5</samples>
              <resolution>1</resolution>
              <min_angle>-0.25</min_angle>
              <max_angle>0.25</max_angle>
            </horizontal>
            <vertical>
              <samples>5</samples>
              <resolution>1</resolution>
              <min_angle>-0.25</min_angle>
              <max_angle>0.25</max_angle>
            </vertical>
          </scan>
          <range>
            <min>0.02</min>
            <max>2</max>
            <resolution>0.01</resolution>
          </range>
        </ray>
        <pose>-0.183 0.183 0.2715 0 -0 2.35619</pose>
      </sensor>
      <velocity_decay>
        <linear>0</linear>
        <angular>0</angular>
      </velocity_decay>
      <gravity>1</gravity>
      <velocity_decay>
        <linear>0</linear>
        <angular>0</angular>
      </velocity_decay>
      <self_collide>0</self_collide>
    </link>
    <link name='torso_lift_link'>
      <pose>-0.062 0 0.8785 0 -0 0</pose>
      <inertial>
        <pose>0.04361 -0.00116 -0.17334 0 -0 0</pose>
        <mass>6.93198</mass>
        <inertia>
          <ixx>0.24487</ixx>
          <ixy>-0.001456</ixy>
          <ixz>-0.009742</ixz>
          <iyy>0.249269</iyy>
          <iyz>0.008281</iyz>
          <izz>0.090395</izz>
        </inertia>
      </inertial>
      <collision name='torso_lift_link_collision'>
        <pose>0 0 0 0 -0 0</pose>
        <geometry>
          <mesh>
            <scale>1 1 1</scale>
            <uri>models/tiago/tiago_description/meshes/torso/torso_lift_collision.dae</uri>
          </mesh>
        </geometry>
      </collision>
      <visual name='torso_lift_link_visual'>
        <pose>0 0 0 0 -0 0</pose>
        <geometry>
          <mesh>
            <scale>1 1 1</scale>
            <uri>models/tiago/tiago_description/meshes/torso/torso_lift_with_arm.stl</uri>
          </mesh>
        </geometry>
      </visual>
      <velocity_decay>
        <linear>0</linear>
        <angular>0</angular>
      </velocity_decay>
    </link>
    <joint name='torso_lift_joint' type='prismatic'>
      <child>torso_lift_link</child>
      <parent>base_footprint</parent>
      <axis>
        <xyz>0 0 1</xyz>
        <limit>
          <lower>0</lower>
          <upper>0.35</upper>
          <effort>2000</effort>
          <velocity>0.07</velocity>
        </limit>
        <dynamics>
          <damping>1000</damping>
        </dynamics>
      </axis>
    </joint>

    <link name='head_1_link'>
      <pose>0.12 0 0.8785 0 -0 0</pose>
      <inertial>
        <pose>-0.00508 0.00237 0.07229 0 -0 0</pose>
        <mass>0.6222</mass>
        <inertia>
          <ixx>0.001192</ixx>
          <ixy>-7e-06</ixy>
          <ixz>9.6e-05</ixz>
          <iyy>0.001402</iyy>
          <iyz>4e-06</iyz>
          <izz>0.000889</izz>
        </inertia>
      </inertial>
      <collision name='head_1_link_collision'>
        <pose>0 0 0 0 -0 0</pose>
        <geometry>
          <mesh>
            <scale>1 1 1</scale>
            <uri>models/tiago/tiago_description/meshes/head/head_1_collision.dae</uri>
          </mesh>
        </geometry>
        <surface>
          <contact>
            <ode/>
          </contact>
          <friction>
            <ode>
              <mu>0.9</mu>
              <mu2>0.9</mu2>
            </ode>
          </friction>
        </surface>
      </collision>
      <visual name='head_1_link_visual'>
        <pose>0 0 0 0 -0 0</pose>
        <geometry>
          <mesh>
            <scale>1 1 1</scale>
            <uri>models/tiago/tiago_description/meshes/head/head_1.stl</uri>
          </mesh>
        </geometry>
      </visual>
      <gravity>1</gravity>
      <velocity_decay>
        <linear>0</linear>
        <angular>0</angular>
      </velocity_decay>
      <self_collide>0</self_collide>
    </link>
    <joint name='head_1_joint' type='revolute'>
      <child>head_1_link</child>
      <parent>torso_lift_link</parent>
      <axis>
        <xyz>0 0 1</xyz>
        <limit>
          <lower>-1.309</lower>
          <upper>1.309</upper>
          <effort>5.197</effort>
          <velocity>3</velocity>
        </limit>
        <dynamics>
          <damping>0.5</damping>
        </dynamics>
      </axis>
      <physics>
        <ode>
          <implicit_spring_damper>1</implicit_spring_damper>
          <cfm_damping>1</cfm_damping>
          <limit>
            <cfm>0</cfm>
            <erp>0.2</erp>
          </limit>
        </ode>
      </physics>
    </joint>
    <link name='head_2_link'>
      <pose>0.125 0 0.9765 1.5708 -0 0</pose>
      <inertial>
        <pose>0.0557879 0.0609773 1.13571e-05 0 -0 0</pose>
        <mass>0.88593</mass>
        <inertia>
          <ixx>0.00476064</ixx>
          <ixy>0.000561581</ixy>
          <ixz>1.2081e-05</ixz>
          <iyy>0.00512284</iyy>
          <iyz>9.40226e-06</iyz>
          <izz>0.00346439</izz>
        </inertia>
      </inertial>
      <collision name='head_2_link_collision'>
        <pose>0 0 0 0 -0 0</pose>
        <geometry>
          <mesh>
            <scale>1 1 1</scale>
            <uri>models/tiago/tiago_description/meshes/head/head_2_collision.dae</uri>
          </mesh>
        </geometry>
      </collision>
      <visual name='head_2_link_visual'>
        <pose>0 0 0 0 -0 0</pose>
        <geometry>
          <mesh>
            <scale>1 1 1</scale>
            <uri>models/tiago/tiago_description/meshes/head/head_2.stl</uri>
          </mesh>
        </geometry>
      </visual>
      <gravity>1</gravity>
      <velocity_decay>
        <linear>0</linear>
        <angular>0</angular>
      </velocity_decay>
      <self_collide>0</self_collide>
    </link>

  	<joint name="xtion_joint" type="fixed">
		<origin rpy="-1.57079632679 0 0" xyz="0.0908 0.08 0"/>
		<pose>0.0908 0.08 0 -1.57079632679 0 0</pose>
		<parent>head_2_link</parent>
		<child>xtion_link</child>
  	</joint>

  	<link name="xtion_link">
		<inertial>
		  <origin rpy="0 0 0" xyz="-0.00936000000 -0.00003000000 -0.00273000000"/>
		  <mass value="0.21970000000"/>
		  <inertia ixx="0.00000429247" ixy="0.00000000000" ixz="0.00000002565" iyy="0.00000008027" iyz="0.00000000000" izz="0.00000427339"/>
		</inertial>
	  <pose>0.25 0 1.05 0 0 0</pose>
      <visual name='xtion_link_visual'>
        <pose>0 0 0 0 -0 0</pose>
        <geometry>
          <mesh>
            <scale>1 1 1</scale>
            <uri>models/tiago/tiago_description/meshes/sensors/xtion_pro_live/xtion_pro_live.stl</uri>
          </mesh>
        </geometry>
      </visual>

     <sensor name='xtion_frame_sensor' type='depth'>
        <always_on>1</always_on>
        <update_rate>30</update_rate>
        <camera name='__default__'>
          <horizontal_fov>1.01229</horizontal_fov>
          <image>
            <format>B8G8R8</format>
            <width>640</width>
            <height>480</height>
          </image>
          <clip>
            <near>0.3</near>
            <far>8</far>
          </clip>
        </camera>
        <!--<pose>0.0908 0.08 -0.022 -1.5708 0 0</pose>-->
        <!-- <plugin name="DepthCameraPlugin" filename="plugins/libDepthCameraPlugin.so"></plugin> -->
      </sensor>

  	</link>

  	<joint name="xtion_optical_joint" type="fixed">
		<origin rpy="-1.57079632679 0.0 -1.57079632679" xyz="0 0 0"/>
		<parent>xtion_link</parent>
		<child>xtion_optical_frame</child>
  	</joint>

	<link name="xtion_optical_frame">
		<inertial>
		  <origin rpy="0 0 0" xyz="0 0 0"/>
		  <mass value="0.001"/>
		  <inertia ixx="0.00001" ixy="0" ixz="0" iyy="0.00001" iyz="0" izz="0.00001"/>
		</inertial>
  	</link>
	
	<!-- frames of the depth sensor -->
	 	
	<joint name="xtion_depth_joint" type="fixed">
		<origin rpy="0 0 0" xyz="0.0 0.049 0.0"/>
		<parent>xtion_link</parent>
		<child>xtion_depth_frame</child>
  	</joint>

  	<link name="xtion_depth_frame">
		<inertial>
		  <origin rpy="0 0 0" xyz="0 0 0"/>
		  <mass value="0.001"/>
		  <inertia ixx="0.00001" ixy="0" ixz="0" iyy="0.00001" iyz="0" izz="0.00001"/>
		</inertial>
  	</link>

  	<joint name="xtion_depth_optical_joint" type="fixed">
		<origin rpy="-1.57079632679 0.0 -1.57079632679" xyz="0 0 0"/>
		<parent>xtion_depth_frame</parent>
		<child>xtion_depth_optical_frame</child>
  	</joint>

  	<link name="xtion_depth_optical_frame">
		<inertial>
		  <origin rpy="0 0 0" xyz="0 0 0"/>
		  <mass value="0.001"/>
		  <inertia ixx="0.00001" ixy="0" ixz="0" iyy="0.00001" iyz="0" izz="0.00001"/>
		</inertial>
  	</link>

	<!-- frames of the rgb sensor -->
  	<joint name="xtion_rgb_joint" type="fixed">
		<origin rpy="0 0 0" xyz="0.0 0.022 0.0"/>
		<parent>xtion_link</parent>
		<child>xtion_rgb_frame</child>
  	</joint>

  	<link name="xtion_rgb_frame">
		<inertial>
		  <origin rpy="0 0 0" xyz="0 0 0"/>
		  <mass value="0.001"/>
		  <inertia ixx="0.00001" ixy="0" ixz="0" iyy="0.00001" iyz="0" izz="0.00001"/>
		</inertial>
  	</link>

  	<joint name="xtion_rgb_optical_joint" type="fixed">
		<origin rpy="-1.57079632679 0.0 -1.57079632679" xyz="0 0 0"/>
		<parent>xtion_rgb_frame</parent>
		<child>xtion_rgb_optical_frame</child>
  	</joint>

  	<link name="xtion_rgb_optical_frame">
		<inertial>
		  <origin rpy="0 0 0" xyz="0 0 0"/>
		  <mass value="0.001"/>
		  <inertia ixx="0.00001" ixy="0" ixz="0" iyy="0.00001" iyz="0" izz="0.00001"/>
		</inertial>
  	</link>

    <joint name='head_2_joint' type='revolute'>
      <child>head_2_link</child>
      <parent>head_1_link</parent>
      <axis>
        <xyz>0 -1 4.89658e-12</xyz>
        <limit>
          <lower>-1.0472</lower>
          <upper>0.785398</upper>
          <effort>2.77</effort>
          <velocity>3</velocity>
        </limit>
        <dynamics>
          <damping>0.5</damping>
        </dynamics>
      </axis>
    </joint>
    <link name='wheel_left_link'>
      <pose>0 0.2022 0.0985 -1.5708 0 0</pose>
      <inertial>
        <pose>0 0 0.00207 0 -0 0</pose>
        <mass>1.82362</mass>
        <inertia>
          <ixx>0.00499743</ixx>
          <ixy>-4.464e-08</ixy>
          <ixz>-2.245e-08</ixz>
          <iyy>0.00499742</iyy>
          <iyz>1.64e-09</iyz>
          <izz>0.0083924</izz>
        </inertia>
      </inertial>
      <collision name='wheel_left_link_collision'>
        <pose>0 0 0 0 -0 0</pose>
        <geometry>
          <cylinder>
            <length>0.04</length>
            <radius>0.0985</radius>
          </cylinder>
        </geometry>
        <surface>
          <contact>
            <ode>
              <kp>1e+06</kp>
              <kd>100</kd>
              <max_vel>1</max_vel>
              <min_depth>0.003</min_depth>
            </ode>
          </contact>
          <friction>
            <ode>
              <mu>1</mu>
              <mu2>1</mu2>
              <fdir1>1 0 0</fdir1>
            </ode>
          </friction>
        </surface>
      </collision>
      <visual name='wheel_left_link_visual'>
        <pose>0 0 0 3.14159 -0 0</pose>
        <geometry>
          <mesh>
            <scale>1 1 1</scale>
            <uri>models/tiago/pmb2_description/meshes/wheels/wheel.stl</uri>
          </mesh>
        </geometry>
        <material>
          <script>
            <name>Gazebo/DarkGrey</name>
            <uri>__default__</uri>
          </script>
        </material>
      </visual>
      <gravity>1</gravity>
      <velocity_decay>
        <linear>0</linear>
        <angular>0</angular>
      </velocity_decay>
      <self_collide>0</self_collide>
    </link>
    <joint name='wheel_left_joint' type='revolute'>
      <child>wheel_left_link</child>
      <parent>base_footprint</parent>
      <axis>
        <xyz>0 1 4.89658e-12</xyz>
        <limit>
          <lower>-1e+16</lower>
          <upper>1e+16</upper>
        </limit>
        <dynamics/>
      </axis>
    </joint>
    <link name='wheel_right_link'>
      <pose>0 -0.2022 0.0985 -1.5708 0 0</pose>
      <inertial>
        <pose>0 0 -0.00207 0 -0 0</pose>
        <mass>1.82362</mass>
        <inertia>
          <ixx>0.00499743</ixx>
          <ixy>4.464e-08</ixy>
          <ixz>-2.245e-08</ixz>
          <iyy>0.00499742</iyy>
          <iyz>-1.64e-09</iyz>
          <izz>0.0083924</izz>
        </inertia>
      </inertial>
      <collision name='wheel_right_link_collision'>
        <pose>0 0 0 0 -0 0</pose>
        <geometry>
          <cylinder>
            <length>0.04</length>
            <radius>0.0985</radius>
          </cylinder>
        </geometry>
        <surface>
          <contact>
            <ode>
              <kp>1e+06</kp>
              <kd>100</kd>
              <max_vel>1</max_vel>
              <min_depth>0.003</min_depth>
            </ode>
          </contact>
          <friction>
            <ode>
              <mu>1</mu>
              <mu2>1</mu2>
              <fdir1>1 0 0</fdir1>
            </ode>
          </friction>
        </surface>
      </collision>
      <visual name='wheel_right_link_visual'>
        <pose>0 0 0 0 -0 0</pose>
        <geometry>
          <mesh>
            <scale>1 1 1</scale>
            <uri>models/tiago/pmb2_description/meshes/wheels/wheel.stl</uri>
          </mesh>
        </geometry>
        <material>
          <script>
            <name>Gazebo/DarkGrey</name>
            <uri>__default__</uri>
          </script>
        </material>
      </visual>
      <gravity>1</gravity>
      <velocity_decay>
        <linear>0</linear>
        <angular>0</angular>
      </velocity_decay>
      <self_collide>0</self_collide>
    </link>
    <joint name='wheel_right_joint' type='revolute'>
      <child>wheel_right_link</child>
      <parent>base_footprint</parent>
      <axis>
        <xyz>0 1 4.89658e-12</xyz>
        <limit>
          <lower>-1e+16</lower>
          <upper>1e+16</upper>
        </limit>
        <dynamics/>
      </axis>
    </joint>
    <static>0</static>
  </model>
</sdf>
